Workbook

Sheet Barison
A1: Barison Romeo
H6: Catégorie | Y6: Libre | AO6: Cadre | BF6: 1bande | BW6: 3bandes Match | CM6: 3bandes 1/4match | DD6: 3bandes Match conv.
H8: Pts | L8: Rep | P8: Moy | Y8: =IF(N38="",0,N38)+IF(AD129="",0,AD129)+IF(BF129="",0,BF129)+IF(CX129="",0,CX129) -> 258 | AC8: =IF(R38="",0,R38)+IF(AG129="",0,AG129)+IF(BJ129="",0,BJ129)+IF(DB129="",0,DB129) -> 120 | AG8: =IF(Y8=0,0,ROUNDDOWN(Y8/AC8,3)) -> 2.15 | AO8: =IF(BF38="",0,BF38)+IF(AC152="",0,AC152)+IF(BF152="",0,BF152) -> 0 | AS8: =IF(BJ38="",0,BJ38)+IF(AG152="",0,AG152)+IF(BJ152="",0,BJ152) -> 0 | AW8: =IF(AO8=0,0,ROUNDDOWN(AO8/AS8,3)) -> 0 | BF8: =IF(CX152="",0,CX152)+IF(AC175="",0,AC175) -> 0 | BJ8: =IF(DB152="",0,DB152)+IF(AG175="",0,AG175) -> 0 | BN8: =IF(BF8=0,0,ROUNDDOWN(BF8/BJ8,3)) -> 0 | BW8: =IF(CX38="",0,CX38)+IF(N69="",0,N69)+IF(N198="",0,N198)+IF(BF198="",0,BF198)+IF(CX198="",0,CX198)+IF(BF175="",0,BF175) -> 0 | CA8: =IF(DB38="",0,DB38)+IF(R69="",0,R69)+IF(R198="",0,R198)+IF(BJ198="",0,BJ198)+IF(DB198="",0,DB198)+IF(BJ175="",0,BJ175) -> 0 | CE8: =IF(BW8=0,0,ROUNDDOWN(BW8/CA8,3)) -> 0 | CM8: =IF(BF69="",0,BF69)+IF(AD198="",0,AD198)+IF(BV198="",0,BV198)+IF(DN198="",0,DN198)+IF(CX175="",0,CX175) -> 0 | CQ8: =IF(BJ69="",0,BJ69)+IF(AG198="",0,AG198)+IF(BY198="",0,BY198)+IF(DQ198="",0,DQ198)+IF(DB175="",0,DB175) -> 0 | CU8: =IF(CM8=0,0,ROUNDDOWN(CM8/CQ8,3)) -> 0 | DD8: =SUM(BW8+(CM8*0.7)) -> 0 | DH8: =SUM(CA8+CQ8) -> 0 | DL8: =IF(DD8=0,0,ROUNDDOWN(DD8/DH8,3)) -> 0
A12: Libre | AS12: Cadre | CK12: 3bandes Billard Match
H14: Date | N14: Pts | R14: Rep | U14: Moy. | Y14: Série | AC14: Advers. | AJ14: Equipe | AZ14: Date | BF14: Pts | BJ14: Rep | BM14: Moy. | BQ14: Série | BU14: Advers. | CB14: Equipe | CR14: Date | CX14: Pts | DB14: Rep | DE14: Moy. | DI14: Série | DM14: Advers. | DT14: Equipe
A16: ITC Classique | D16: J 1 | H16: 46041 | N16: 57 | R16: 20 | U16: =IF(H16="","",ROUNDDOWN(N16/R16,3)) -> 2.85 | Y16: 25 | AC16: Soares A. | AJ16: DUD2 | AS16: ITC Classique | AV16: J 1 | BM16: =IF(AZ16="","",ROUNDDOWN(BF16/BJ16,3)) | CK16: ITC Classique | CN16: J 1 | DE16: =IF(CR16="","",ROUNDDOWN(CX16/DB16,3))
D18: J 2 | H18: 46048 | N18: 27 | R18: 20 | U18: =IF(H18="","",ROUNDDOWN(N18/R18,3)) -> 1.35 | Y18: 6 | AC18: Leclerc Ph. | AJ18: DUD2 | AV18: J 2 | BM18: =IF(AZ18="","",ROUNDDOWN(BF18/BJ18,3)) | CN18: J 2 | DE18: =IF(CR18="","",ROUNDDOWN(CX18/DB18,3))
D20: J 3 | H20: 46055 | N20: 51 | R20: 20 | U20: =IF(H20="","",ROUNDDOWN(N20/R20,3)) -> 2.55 | Y20: 17 | AC20: D'Hoest F. | AJ20: DUD1 | AV20: J 3 | BM20: =IF(AZ20="","",ROUNDDOWN(BF20/BJ20,3)) | CN20: J 3 | DE20: =IF(CR20="","",ROUNDDOWN(CX20/DB20,3))
D22: J 4 | H22: 46062 | N22: 17 | R22: 20 | U22: =IF(H22="","",ROUNDDOWN(N22/R22,3)) -> 0.85 | Y22: 4 | AC22: Engel G. | AJ22: DUD2 | AV22: J 4 | BM22: =IF(AZ22="","",ROUNDDOWN(BF22/BJ22,3)) | CN22: J 4 | DE22: =IF(CR22="","",ROUNDDOWN(CX22/DB22,3))
D24: J 5 | H24: 46076 | N24: 53 | R24: 20 | U24: =IF(H24="","",ROUNDDOWN(N24/R24,3)) -> 2.65 | Y24: 11 | AC24: Rommes R. | AJ24: DUD1 | AV24: J 5 | BM24: =IF(AZ24="","",ROUNDDOWN(BF24/BJ24,3)) | CN24: J 5 | DE24: =IF(CR24="","",ROUNDDOWN(CX24/DB24,3))
D26: J 6 | H26: 46083 | N26: 53 | R26: 20 | U26: =IF(H26="","",ROUNDDOWN(N26/R26,3)) -> 2.65 | Y26: 11 | AC26: Bollini L. | AJ26: DUD1 | AV26: J 6 | BM26: =IF(AZ26="","",ROUNDDOWN(BF26/BJ26,3)) | CN26: J 6 | DE26: =IF(CR26="","",ROUNDDOWN(CX26/DB26,3))
D28: J7 | U28: =IF(H28="","",ROUNDDOWN(N28/R28,3)) | AV28: J7 | BM28: =IF(AZ28="","",ROUNDDOWN(BF28/BJ28,3)) | CN28: J7 | DE28: =IF(CR28="","",ROUNDDOWN(CX28/DB28,3))
D30: J8 | U30: =IF(H30="","",ROUNDDOWN(N30/R30,3)) | AV30: J8 | BM30: =IF(AZ30="","",ROUNDDOWN(BF30/BJ30,3)) | CN30: J8 | DE30: =IF(CR30="","",ROUNDDOWN(CX30/DB30,3))
D32: J9 | U32: =IF(H32="","",ROUNDDOWN(N32/R32,3)) | AV32: J9 | BM32: =IF(AZ32="","",ROUNDDOWN(BF32/BJ32,3)) | CN32: J9 | DE32: =IF(CR32="","",ROUNDDOWN(CX32/DB32,3))
D34: J10 | U34: =IF(H34="","",ROUNDDOWN(N34/R34,3)) | AV34: J10 | BM34: =IF(AZ34="","",ROUNDDOWN(BF34/BJ34,3)) | CN34: J10 | DE34: =IF(CR34="","",ROUNDDOWN(CX34/DB34,3))
N36: =SUM(N16:Q35) -> 258 | U36: =IF(H36="","",ROUNDDOWN(N36/R36,3)) | BF36: =SUM(BF16:BI35) -> 0 | BM36: =IF(AZ36="","",ROUNDDOWN(BF36/BJ36,3)) | CX36: =SUM(CX16:DA35) -> 0 | DE36: =IF(CR36="","",ROUNDDOWN(CX36/DB36,3))
H38: =IF(N36=0,"","Total") -> Total | N38: =IF(H38="","",SUM(N16:Q35)) -> 258 | R38: =IF(H38="","",SUM(R16:T35)) -> 120 | U38: =IF(H38="","",ROUNDDOWN(N38/R38,3)) -> 2.15 | AZ38: =IF(BF36=0,"","Total") | BF38: =IF(AZ38="","",SUM(BF16:BI35)) | BJ38: =IF(AZ38="","",SUM(BJ16:BL35)) | BM38: =IF(AZ38="","",ROUNDDOWN(BF38/BJ38,3)) | CR38: =IF(CX36=0,"","Total") | CX38: =IF(CR38="","",SUM(CX16:DA35)) | DB38: =IF(CR38="","",SUM(DB16:DD35)) | DE38: =IF(CR38="","",ROUNDDOWN(CX38/DB38,3))
Z39: Matchs en 1. équipe
A43: 3bandes Billard Match | AS43: 3bandes Billard 1/4 match
H45: Date | N45: Pts | R45: Rep | U45: Moy. | Y45: Série | AC45: Advers. | AJ45: Equipe | AZ45: Date | BF45: Pts | BJ45: Rep | BM45: Moy. | BQ45: Série | BU45: Advers. | CB45: Equipe
A47: ITC 3bandes | D47: J 1 | U47: =IF(H47="","",ROUNDDOWN(N47/R47,3)) | AS47: ITC 3bandes | AV47: J 1 | BM47: =IF(AZ47="","",ROUNDDOWN(BF47/BJ47,3))
D49: J 2 | U49: =IF(H49="","",ROUNDDOWN(N49/R49,3)) | AV49: J 2 | BM49: =IF(AZ49="","",ROUNDDOWN(BF49/BJ49,3))
D51: J 3 | U51: =IF(H51="","",ROUNDDOWN(N51/R51,3)) | AV51: J 3 | BM51: =IF(AZ51="","",ROUNDDOWN(BF51/BJ51,3))
D53: J 4 | U53: =IF(H53="","",ROUNDDOWN(N53/R53,3)) | AV53: J 4 | BM53: =IF(AZ53="","",ROUNDDOWN(BF53/BJ53,3))
D55: J 5 | U55: =IF(H55="","",ROUNDDOWN(N55/R55,3)) | AV55: J 5 | BM55: =IF(AZ55="","",ROUNDDOWN(BF55/BJ55,3))
D57: J 6 | U57: =IF(H57="","",ROUNDDOWN(N57/R57,3)) | AV57: J 6 | BM57: =IF(AZ57="","",ROUNDDOWN(BF57/BJ57,3))
D59: J7 | U59: =IF(H59="","",ROUNDDOWN(N59/R59,3)) | AV59: J7 | BM59: =IF(AZ59="","",ROUNDDOWN(BF59/BJ59,3))
D61: J8 | U61: =IF(H61="","",ROUNDDOWN(N61/R61,3)) | AV61: J8 | BM61: =IF(AZ61="","",ROUNDDOWN(BF61/BJ61,3))
D63: J9 | U63: =IF(H63="","",ROUNDDOWN(N63/R63,3)) | AV63: J9 | BM63: =IF(AZ63="","",ROUNDDOWN(BF63/BJ63,3))
D65: J10 | U65: =IF(H65="","",ROUNDDOWN(N65/R65,3)) | AV65: J10 | BM65: =IF(AZ65="","",ROUNDDOWN(BF65/BJ65,3))
N67: =SUM(N47:Q66) -> 0 | U67: =IF(H67="","",ROUNDDOWN(N67/R67,3)) | BF67: =SUM(BF47:BI66) -> 0 | BM67: =IF(AZ67="","",ROUNDDOWN(BF67/BJ67,3))
H69: =IF(N67=0,"","Total") | N69: =IF(H69="","",SUM(N47:Q66)) | R69: =IF(H69="","",SUM(R47:T66)) | U69: =IF(H69="","",ROUNDDOWN(N69/R69,3)) | AZ69: =IF(BF67=0,"","Total") | BF69: =IF(AZ69="","",SUM(BF47:BI66)) | BJ69: =IF(AZ69="","",SUM(BJ47:BL66)) | BM69: =IF(AZ69="","",ROUNDDOWN(BF69/BJ69,3))
H73: 2 Matchs pour moyenne
A111: Individuel Libre Match | AS111: Individuel Libre 1/4match | CK111: Individuel Handycap
H113: Date | N113: Pts | R113: Rep | U113: Moy. | Y113: Série | AC113: Advers. | AJ113: Equipe | AZ113: Date | BF113: Pts | BJ113: Rep | BM113: Moy. | BQ113: Série | BU113: Advers. | CB113: Equipe | CR113: Date | CX113: Pts | DB113: Rep | DE113: Moy. | DI113: Série | DM113: Advers. | DT113: Equipe
U115: =IF(H115="","",ROUNDDOWN(N115/R115,3)) | BM115: =IF(AZ115="","",ROUNDDOWN(BF115/BJ115,3)) | DE115: =IF(CR115="","",ROUNDDOWN(CX115/DB115,3))
U117: =IF(H117="","",ROUNDDOWN(N117/R117,3)) | BM117: =IF(AZ117="","",ROUNDDOWN(BF117/BJ117,3)) | DE117: =IF(CR117="","",ROUNDDOWN(CX117/DB117,3))
U119: =IF(H119="","",ROUNDDOWN(N119/R119,3)) | BM119: =IF(AZ119="","",ROUNDDOWN(BF119/BJ119,3)) | DE119: =IF(CR119="","",ROUNDDOWN(CX119/DB119,3))
U121: =IF(H121="","",ROUNDDOWN(N121/R121,3)) | BM121: =IF(AZ121="","",ROUNDDOWN(BF121/BJ121,3)) | DE121: =IF(CR121="","",ROUNDDOWN(CX121/DB121,3))
U123: =IF(H123="","",ROUNDDOWN(N123/R123,3)) | BM123: =IF(AZ123="","",ROUNDDOWN(BF123/BJ123,3)) | DE123: =IF(CR123="","",ROUNDDOWN(CX123/DB123,3))
...

Sheet Beck
A1: Beck Johny
H6: Catégorie | Y6: Libre | AO6: Cadre | BF6: 1bande | BW6: 3bandes Match | CM6: 3bandes 1/4match | DD6: 3bandes Match conv.
H8: Pts | L8: Rep | P8: Moy | Y8: =IF(N38="",0,N38)+IF(AD130="",0,AD130)+IF(BF130="",0,BF130)+IF(CX130="",0,CX130) -> 0 | AC8: =IF(R38="",0,R38)+IF(AG130="",0,AG130)+IF(BJ130="",0,BJ130)+IF(DB130="",0,DB130) -> 0 | AG8: =IF(Y8=0,0,ROUNDDOWN(Y8/AC8,3)) -> 0 | AO8: =IF(BF38="",0,BF38)+IF(AC153="",0,AC153)+IF(BF153="",0,BF153) -> 213 | AS8: =IF(BJ38="",0,BJ38)+IF(AG153="",0,AG153)+IF(BJ153="",0,BJ153) -> 94 | AW8: =IF(AO8=0,0,ROUNDDOWN(AO8/AS8,3)) -> 2.265 | BF8: =IF(CX153="",0,CX153)+IF(AC176="",0,AC176) -> 0 | BJ8: =IF(DB153="",0,DB153)+IF(AG176="",0,AG176) -> 0 | BN8: =IF(BF8=0,0,ROUNDDOWN(BF8/BJ8,3)) -> 0 | BW8: =IF(CX38="",0,CX38)+IF(N69="",0,N69)+IF(N199="",0,N199)+IF(BF199="",0,BF199)+IF(CX199="",0,CX199)+IF(BF176="",0,BF176) -> 0 | CA8: =IF(DB38="",0,DB38)+IF(R69="",0,R69)+IF(R199="",0,R199)+IF(BJ199="",0,BJ199)+IF(DB199="",0,DB199)+IF(BJ176="",0,BJ176) -> 0 | CE8: =IF(BW8=0,0,ROUNDDOWN(BW8/CA8,3)) -> 0 | CM8: =IF(BF69="",0,BF69)+IF(AD199="",0,AD199)+IF(BV199="",0,BV199)+IF(DN199="",0,DN199)+IF(CX176="",0,CX176) -> 59 | CQ8: =IF(BJ69="",0,BJ69)+IF(AG199="",0,AG199)+IF(BY199="",0,BY199)+IF(DQ199="",0,DQ199)+IF(DB176="",0,DB176) -> 160 | CU8: =IF(CM8=0,0,ROUNDDOWN(CM8/CQ8,3)) -> 0.368 | DD8: =SUM(BW8+(CM8*0.7)) -> 41.3 | DH8: =SUM(CA8+CQ8) -> 160 | DL8: =IF(DD8=0,0,ROUNDDOWN(DD8/DH8,3)) -> 0.258
A12: Libre | AS12: Cadre | CK12: 3bandes Billard Match
H14: Date | N14: Pts | R14: Rep | U14: Moy. | Y14: Série | AC14: Advers. | AJ14: Equipe | AZ14: Date | BF14: Pts | BJ14: Rep | BM14: Moy. | BQ14: Série | BU14: Advers. | CB14: Equipe | CR14: Date | CX14: Pts | DB14: Rep | DE14: Moy. | DI14: Série | DM14: Advers. | DT14: Equipe
A16: ITC Classique | D16: J 1 | U16: =IF(H16="","",ROUNDDOWN(N16/R16,3)) | AS16: ITC Classique | AV16: J 1 | BM16: =IF(AZ16="","",ROUNDDOWN(BF16/BJ16,3)) | CK16: ITC Classique | CN16: J 1 | DE16: =IF(CR16="","",ROUNDDOWN(CX16/DB16,3))
D18: J 2 | U18: =IF(H18="","",ROUNDDOWN(N18/R18,3)) | AV18: J 2 | BM18: =IF(AZ18="","",ROUNDDOWN(BF18/BJ18,3)) | CN18: J 2 | DE18: =IF(CR18="","",ROUNDDOWN(CX18/DB18,3))
D20: J 3 | U20: =IF(H20="","",ROUNDDOWN(N20/R20,3)) | AV20: J 3 | BM20: =IF(AZ20="","",ROUNDDOWN(BF20/BJ20,3)) | CN20: J 3 | DE20: =IF(CR20="","",ROUNDDOWN(CX20/DB20,3))
D22: J 4 | U22: =IF(H22="","",ROUNDDOWN(N22/R22,3)) | AV22: J 4 | AZ22: 46062 | BF22: 75 | BJ22: 20 | BM22: =IF(AZ22="","",ROUNDDOWN(BF22/BJ22,3)) -> 3.75 | BQ22: 16 | BU22: Drye M. | CB22: DUD1 | CN22: J 4 | DE22: =IF(CR22="","",ROUNDDOWN(CX22/DB22,3))
D24: J 5 | U24: =IF(H24="","",ROUNDDOWN(N24/R24,3)) | AV24: J 5 | BM24: =IF(AZ24="","",ROUNDDOWN(BF24/BJ24,3)) | CN24: J 5 | DE24: =IF(CR24="","",ROUNDDOWN(CX24/DB24,3))
D26: J 6 | U26: =IF(H26="","",ROUNDDOWN(N26/R26,3)) | AV26: J 6 | BM26: =IF(AZ26="","",ROUNDDOWN(BF26/BJ26,3)) | CN26: J 6 | DE26: =IF(CR26="","",ROUNDDOWN(CX26/DB26,3))
D28: J7 | U28: =IF(H28="","",ROUNDDOWN(N28/R28,3)) | AV28: J7 | BM28: =IF(AZ28="","",ROUNDDOWN(BF28/BJ28,3)) | CN28: J7 | DE28: =IF(CR28="","",ROUNDDOWN(CX28/DB28,3))
D30: J8 | U30: =IF(H30="","",ROUNDDOWN(N30/R30,3)) | AV30: J8 | BM30: =IF(AZ30="","",ROUNDDOWN(BF30/BJ30,3)) | CN30: J8 | DE30: =IF(CR30="","",ROUNDDOWN(CX30/DB30,3))
D32: J9 | U32: =IF(H32="","",ROUNDDOWN(N32/R32,3)) | AV32: J9 | BM32: =IF(AZ32="","",ROUNDDOWN(BF32/BJ32,3)) | CN32: J9 | DE32: =IF(CR32="","",ROUNDDOWN(CX32/DB32,3))
D34: J10 | U34: =IF(H34="","",ROUNDDOWN(N34/R34,3)) | AV34: J10 | BM34: =IF(AZ34="","",ROUNDDOWN(BF34/BJ34,3)) | CN34: J10 | DE34: =IF(CR34="","",ROUNDDOWN(CX34/DB34,3))
N36: =SUM(N16:Q35) -> 0 | U36: =IF(H36="","",ROUNDDOWN(N36/R36,3)) | BF36: =SUM(BF16:BI35) -> 75 | BM36: =IF(AZ36="","",ROUNDDOWN(BF36/BJ36,3)) | CX36: =SUM(CX16:DA35) -> 0 | DE36: =IF(CR36="","",ROUNDDOWN(CX36/DB36,3))
H38: =IF(N36=0,"","Total") | N38: =IF(H38="","",SUM(N16:Q35)) | R38: =IF(H38="","",SUM(R16:T35)) | U38: =IF(H38="","",ROUNDDOWN(N38/R38,3)) | AZ38: =IF(BF36=0,"","Total") -> Total | BF38: =IF(AZ38="","",SUM(BF16:BI35)) -> 75 | BJ38: =IF(AZ38="","",SUM(BJ16:BL35)) -> 20 | BM38: =IF(AZ38="","",ROUNDDOWN(BF38/BJ38,3)) -> 3.75 | CR38: =IF(CX36=0,"","Total") | CX38: =IF(CR38="","",SUM(CX16:DA35)) | DB38: =IF(CR38="","",SUM(DB16:DD35)) | DE38: =IF(CR38="","",ROUNDDOWN(CX38/DB38,3))
A43: 3bandes Billard Match | AS43: 3bandes Billard 1/4 match
H45: Date | N45: Pts | R45: Rep | U45: Moy. | Y45: Série | AC45: Advers. | AJ45: Equipe | AZ45: Date | BF45: Pts | BJ45: Rep | BM45: Moy. | BQ45: Série | BU45: Advers. | CB45: Equipe
A47: ITC 3bandes | D47: J 1 | U47: =IF(H47="","",ROUNDDOWN(N47/R47,3)) | AS47: ITC 3bandes | AV47: J 1 | AZ47: 45915 | BF47: 18 | BJ47: 40 | BM47: =IF(AZ47="","",ROUNDDOWN(BF47/BJ47,3)) -> 0.45 | BQ47: 2 | BU47: Biver R. | CB47: DUD2
D49: J 2 | U49: =IF(H49="","",ROUNDDOWN(N49/R49,3)) | AV49: J 2 | AZ49: 45922 | BF49: 10 | BJ49: 40 | BM49: =IF(AZ49="","",ROUNDDOWN(BF49/BJ49,3)) -> 0.25 | BQ49: 2 | BU49: Brüls I. | CB49: DUD2
D51: J 3 | U51: =IF(H51="","",ROUNDDOWN(N51/R51,3)) | AV51: J 3 | AZ51: 45929 | BF51: 16 | BJ51: 40 | BM51: =IF(AZ51="","",ROUNDDOWN(BF51/BJ51,3)) -> 0.4 | BQ51: 5 | BU51: Kihn D. | CB51: DUD2
D53: J 4 | U53: =IF(H53="","",ROUNDDOWN(N53/R53,3)) | AV53: J 4 | BM53: =IF(AZ53="","",ROUNDDOWN(BF53/BJ53,3))
D55: J 5 | U55: =IF(H55="","",ROUNDDOWN(N55/R55,3)) | AV55: J 5 | BM55: =IF(AZ55="","",ROUNDDOWN(BF55/BJ55,3))
D57: J 6 | U57: =IF(H57="","",ROUNDDOWN(N57/R57,3)) | AV57: J 6 | AZ57: 45950 | BF57: 15 | BJ57: 40 | BM57: =IF(AZ57="","",ROUNDDOWN(BF57/BJ57,3)) -> 0.375 | BQ57: 3 | BU57: Pallucca C. | CB57: DUD2
D59: J7 | U59: =IF(H59="","",ROUNDDOWN(N59/R59,3)) | AV59: J7 | BM59: =IF(AZ59="","",ROUNDDOWN(BF59/BJ59,3))
D61: J8 | U61: =IF(H61="","",ROUNDDOWN(N61/R61,3)) | AV61: J8 | BM61: =IF(AZ61="","",ROUNDDOWN(BF61/BJ61,3))
D63: J9 | U63: =IF(H63="","",ROUNDDOWN(N63/R63,3)) | AV63: J9 | BM63: =IF(AZ63="","",ROUNDDOWN(BF63/BJ63,3))
D65: J10 | U65: =IF(H65="","",ROUNDDOWN(N65/R65,3)) | AV65: J10 | BM65: =IF(AZ65="","",ROUNDDOWN(BF65/BJ65,3))
N67: =SUM(N47:Q66) -> 0 | U67: =IF(H67="","",ROUNDDOWN(N67/R67,3)) | BF67: =SUM(BF47:BI66) -> 59 | BM67: =IF(AZ67="","",ROUNDDOWN(BF67/BJ67,3))
H69: =IF(N67=0,"","Total") | N69: =IF(H69="","",SUM(N47:Q66)) | R69: =IF(H69="","",SUM(R47:T66)) | U69: =IF(H69="","",ROUNDDOWN(N69/R69,3)) | AZ69: =IF(BF67=0,"","Total") -> Total | BF69: =IF(AZ69="","",SUM(BF47:BI66)) -> 59 | BJ69: =IF(AZ69="","",SUM(BJ47:BL66)) -> 160 | BM69: =IF(AZ69="","",ROUNDDOWN(BF69/BJ69,3)) -> 0.368
A112: Individuel Libre Match | AS112: Individuel Libre 1/4match | CK112: Individuel Handycap
H114: Date | N114: Pts | R114: Rep | U114: Moy. | Y114: Série | AC114: Advers. | AJ114: Equipe | AZ114: Date | BF114: Pts | BJ114: Rep | BM114: Moy. | BQ114: Série | BU114: Advers. | CB114: Equipe | CR114: Date | CX114: Pts | DB114: Rep | DE114: Moy. | DI114: Série | DM114: Advers. | DT114: Equipe
U116: =IF(H116="","",ROUNDDOWN(N116/R116,3)) | BM116: =IF(AZ116="","",ROUNDDOWN(BF116/BJ116,3)) | DE116: =IF(CR116="","",ROUNDDOWN(CX116/DB116,3))
U118: =IF(H118="","",ROUNDDOWN(N118/R118,3)) | BM118: =IF(AZ118="","",ROUNDDOWN(BF118/BJ118,3)) | DE118: =IF(CR118="","",ROUNDDOWN(CX118/DB118,3))
U120: =IF(H120="","",ROUNDDOWN(N120/R120,3)) | BM120: =IF(AZ120="","",ROUNDDOWN(BF120/BJ120,3)) | DE120: =IF(CR120="","",ROUNDDOWN(CX120/DB120,3))
U122: =IF(H122="","",ROUNDDOWN(N122/R122,3)) | BM122: =IF(AZ122="","",ROUNDDOWN(BF122/BJ122,3)) | DE122: =IF(CR122="","",ROUNDDOWN(CX122/DB122,3))
U124: =IF(H124="","",ROUNDDOWN(N124/R124,3)) | BM124: =IF(AZ124="","",ROUNDDOWN(BF124/BJ124,3)) | DE124: =IF(CR124="","",ROUNDDOWN(CX124/DB124,3))
U126: =IF(H126="","",ROUNDDOWN(N126/R126,3)) | BM126: =IF(AZ126="","",ROUNDDOWN(BF126/BJ126,3)) | DE126: =IF(CR126="","",ROUNDDOWN(CX126/DB126,3))
N128: =SUM(N116:Q127) -> 0 | U128: =IF(H128="","",ROUNDDOWN(N128/R128,3)) | BF128: =SUM(BF116:BI127) -> 0 | BM128: =IF(AZ128="","",ROUNDDOWN(BF128/BJ128,3)) | CX128: =SUM(CX116:DA127) -> 0 | DE128: =IF(CR128="","",ROUNDDOWN(CX128/DB128,3))
...

Sheet Biver
A1: Biver Ralph
H6: Catégorie | Y6: Libre | AO6: Cadre | BF6: 1bande | BW6: 3bandes Match | CM6: 3bandes 1/4match | DD6: 3bandes Match conv.
H8: Pts | L8: Rep | P8: Moy | Y8: =IF(N38="",0,N38)+IF(AD130="",0,AD130)+IF(BF130="",0,BF130)+IF(CX130="",0,CX130) -> 0 | AC8: =IF(R38="",0,R38)+IF(AG130="",0,AG130)+IF(BJ130="",0,BJ130)+IF(DB130="",0,DB130) -> 0 | AG8: =IF(Y8=0,0,ROUNDDOWN(Y8/AC8,3)) -> 0 | AO8: =IF(BF38="",0,BF38)+IF(AC153="",0,AC153)+IF(BF153="",0,BF153) -> 146 | AS8: =IF(BJ38="",0,BJ38)+IF(AG153="",0,AG153)+IF(BJ153="",0,BJ153) -> 77 | AW8: =IF(AO8=0,0,ROUNDDOWN(AO8/AS8,3)) -> 1.896 | BF8: =IF(CX153="",0,CX153)+IF(AC176="",0,AC176) -> 214 | BJ8: =IF(DB153="",0,DB153)+IF(AG176="",0,AG176) -> 131 | BN8: =IF(BF8=0,0,ROUNDDOWN(BF8/BJ8,3)) -> 1.633 | BW8: =IF(CX38="",0,CX38)+IF(N69="",0,N69)+IF(N199="",0,N199)+IF(BF199="",0,BF199)+IF(CX199="",0,CX199)+IF(BF176="",0,BF176) -> 271 | CA8: =IF(DB38="",0,DB38)+IF(R69="",0,R69)+IF(R199="",0,R199)+IF(BJ199="",0,BJ199)+IF(DB199="",0,DB199)+IF(BJ176="",0,BJ176) -> 743 | CE8: =IF(BW8=0,0,ROUNDDOWN(BW8/CA8,3)) -> 0.364 | CM8: =IF(BF69="",0,BF69)+IF(AD199="",0,AD199)+IF(BV199="",0,BV199)+IF(DN199="",0,DN199)+IF(CX176="",0,CX176) -> 231 | CQ8: =IF(BJ69="",0,BJ69)+IF(AG199="",0,AG199)+IF(BY199="",0,BY199)+IF(DQ199="",0,DQ199)+IF(DB176="",0,DB176) -> 371 | CU8: =IF(CM8=0,0,ROUNDDOWN(CM8/CQ8,3)) -> 0.622 | DD8: =SUM(BW8+(CM8*0.7)) -> 432.7 | DH8: =SUM(CA8+CQ8) -> 1114 | DL8: =IF(DD8=0,0,ROUNDDOWN(DD8/DH8,3)) -> 0.388
A12: Libre | AS12: Cadre | CK12: 3bandes Billard Match
H14: Date | N14: Pts | R14: Rep | U14: Moy. | Y14: Série | AC14: Advers. | AJ14: Equipe | AZ14: Date | BF14: Pts | BJ14: Rep | BM14: Moy. | BQ14: Série | BU14: Advers. | CB14: Equipe | CR14: Date | CX14: Pts | DB14: Rep | DE14: Moy. | DI14: Série | DM14: Advers. | DT14: Equipe
A16: ITC Classique | D16: J 1 | U16: =IF(H16="","",ROUNDDOWN(N16/R16,3)) | AS16: ITC Classique | AV16: J 1 | BM16: =IF(AZ16="","",ROUNDDOWN(BF16/BJ16,3)) | CK16: ITC Classique | CN16: J 1 | CR16: 46041 | CX16: 22 | DB16: 40 | DE16: =IF(CR16="","",ROUNDDOWN(CX16/DB16,3)) -> 0.55 | DI16: 4 | DM16: Borneque F. | DT16: DUD1
D18: J 2 | U18: =IF(H18="","",ROUNDDOWN(N18/R18,3)) | AV18: J 2 | BM18: =IF(AZ18="","",ROUNDDOWN(BF18/BJ18,3)) | CN18: J 2 | CR18: 46048 | CX18: 7 | DB18: 40 | DE18: =IF(CR18="","",ROUNDDOWN(CX18/DB18,3)) -> 0.175 | DI18: 3 | DM18: Dal Cortivo P. | DT18: DUD1
D20: J 3 | U20: =IF(H20="","",ROUNDDOWN(N20/R20,3)) | AV20: J 3 | BM20: =IF(AZ20="","",ROUNDDOWN(BF20/BJ20,3)) | CN20: J 3 | CR20: 46055 | CX20: 15 | DB20: 40 | DE20: =IF(CR20="","",ROUNDDOWN(CX20/DB20,3)) -> 0.375 | DI20: 4 | DM20: Tempelers B. | DT20: DUD1
D22: J 4 | U22: =IF(H22="","",ROUNDDOWN(N22/R22,3)) | AV22: J 4 | BM22: =IF(AZ22="","",ROUNDDOWN(BF22/BJ22,3)) | CN22: J 4 | CR22: 46062 | CX22: 8 | DB22: 40 | DE22: =IF(CR22="","",ROUNDDOWN(CX22/DB22,3)) -> 0.2 | DI22: 2 | DM22: Lejeune F. | DT22: DUD1
D24: J 5 | U24: =IF(H24="","",ROUNDDOWN(N24/R24,3)) | AV24: J 5 | BM24: =IF(AZ24="","",ROUNDDOWN(BF24/BJ24,3)) | CN24: J 5 | CR24: 46076 | CX24: 12 | DB24: 40 | DE24: =IF(CR24="","",ROUNDDOWN(CX24/DB24,3)) -> 0.3 | DI24: 3 | DM24: Ribeiro A. | DT24: DUD1
D26: J 6 | U26: =IF(H26="","",ROUNDDOWN(N26/R26,3)) | AV26: J 6 | BM26: =IF(AZ26="","",ROUNDDOWN(BF26/BJ26,3)) | CN26: J 6 | CR26: 46083 | CX26: 28 | DB26: 40 | DE26: =IF(CR26="","",ROUNDDOWN(CX26/DB26,3)) -> 0.7 | DI26: 3 | DM26: Schintgen D. | DT26: DUD1
D28: J7 | U28: =IF(H28="","",ROUNDDOWN(N28/R28,3)) | AV28: J7 | BM28: =IF(AZ28="","",ROUNDDOWN(BF28/BJ28,3)) | CN28: J7 | DE28: =IF(CR28="","",ROUNDDOWN(CX28/DB28,3))
D30: J8 | U30: =IF(H30="","",ROUNDDOWN(N30/R30,3)) | AV30: J8 | BM30: =IF(AZ30="","",ROUNDDOWN(BF30/BJ30,3)) | CN30: J8 | DE30: =IF(CR30="","",ROUNDDOWN(CX30/DB30,3))
D32: J9 | U32: =IF(H32="","",ROUNDDOWN(N32/R32,3)) | AV32: J9 | BM32: =IF(AZ32="","",ROUNDDOWN(BF32/BJ32,3)) | CN32: J9 | DE32: =IF(CR32="","",ROUNDDOWN(CX32/DB32,3))
D34: J10 | U34: =IF(H34="","",ROUNDDOWN(N34/R34,3)) | AV34: J10 | BM34: =IF(AZ34="","",ROUNDDOWN(BF34/BJ34,3)) | CN34: J10 | DE34: =IF(CR34="","",ROUNDDOWN(CX34/DB34,3))
N36: =SUM(N16:Q35) -> 0 | U36: =IF(H36="","",ROUNDDOWN(N36/R36,3)) | BF36: =SUM(BF16:BI35) -> 0 | BM36: =IF(AZ36="","",ROUNDDOWN(BF36/BJ36,3)) | CX36: =SUM(CX16:DA35) -> 92 | DE36: =IF(CR36="","",ROUNDDOWN(CX36/DB36,3))
H38: =IF(N36=0,"","Total") | N38: =IF(H38="","",SUM(N16:Q35)) | R38: =IF(H38="","",SUM(R16:T35)) | U38: =IF(H38="","",ROUNDDOWN(N38/R38,3)) | AZ38: =IF(BF36=0,"","Total") | BF38: =IF(AZ38="","",SUM(BF16:BI35)) | BJ38: =IF(AZ38="","",SUM(BJ16:BL35)) | BM38: =IF(AZ38="","",ROUNDDOWN(BF38/BJ38,3)) | CR38: =IF(CX36=0,"","Total") -> Total | CX38: =IF(CR38="","",SUM(CX16:DA35)) -> 92 | DB38: =IF(CR38="","",SUM(DB16:DD35)) -> 240 | DE38: =IF(CR38="","",ROUNDDOWN(CX38/DB38,3)) -> 0.383
A43: 3bandes Billard Match | AS43: 3bandes Billard 1/4 match
H45: Date | N45: Pts | R45: Rep | U45: Moy. | Y45: Série | AC45: Advers. | AJ45: Equipe | AZ45: Date | BF45: Pts | BJ45: Rep | BM45: Moy. | BQ45: Série | BU45: Advers. | CB45: Equipe
A47: ITC 3bandes | D47: J 1 | U47: =IF(H47="","",ROUNDDOWN(N47/R47,3)) | AS47: ITC 3bandes | AV47: J 1 | AZ47: 45915 | BF47: 13 | BJ47: 40 | BM47: =IF(AZ47="","",ROUNDDOWN(BF47/BJ47,3)) -> 0.325 | BQ47: 2 | BU47: Beck J. | CB47: DUD1
D49: J 2 | U49: =IF(H49="","",ROUNDDOWN(N49/R49,3)) | AV49: J 2 | AZ49: 45922 | BF49: 30 | BJ49: 38 | BM49: =IF(AZ49="","",ROUNDDOWN(BF49/BJ49,3)) -> 0.789 | BQ49: 3 | BU49: Jeronimo J. | CB49: DUD1
D51: J 3 | U51: =IF(H51="","",ROUNDDOWN(N51/R51,3)) | AV51: J 3 | AZ51: 45929 | BF51: 21 | BJ51: 40 | BM51: =IF(AZ51="","",ROUNDDOWN(BF51/BJ51,3)) -> 0.525 | BQ51: 3 | BU51: Muller C. | CB51: DUD1
D53: J 4 | U53: =IF(H53="","",ROUNDDOWN(N53/R53,3)) | AV53: J 4 | AZ53: 45936 | BF53: 30 | BJ53: 40 | BM53: =IF(AZ53="","",ROUNDDOWN(BF53/BJ53,3)) -> 0.75 | BQ53: 6 | BU53: Cordero Ch. | CB53: DUD1
D55: J 5 | U55: =IF(H55="","",ROUNDDOWN(N55/R55,3)) | AV55: J 5 | AZ55: 45943 | BF55: 21 | BJ55: 40 | BM55: =IF(AZ55="","",ROUNDDOWN(BF55/BJ55,3)) -> 0.525 | BQ55: 6 | BU55: Gül A. | CB55: DUD1
D57: J 6 | H57: 45950 | N57: 13 | R57: 40 | U57: =IF(H57="","",ROUNDDOWN(N57/R57,3)) -> 0.325 | Y57: 3 | AC57: De Matos R. | AJ57: DUD1 | AV57: J 6 | BM57: =IF(AZ57="","",ROUNDDOWN(BF57/BJ57,3))
D59: J7 | H59: 45957 | N59: 14 | R59: 40 | U59: =IF(H59="","",ROUNDDOWN(N59/R59,3)) -> 0.35 | Y59: 4 | AC59: Schreiner M. | AJ59: DUD1 | AV59: J7 | BM59: =IF(AZ59="","",ROUNDDOWN(BF59/BJ59,3))
D61: J8 | H61: 45971 | N61: 16 | R61: 40 | U61: =IF(H61="","",ROUNDDOWN(N61/R61,3)) -> 0.4 | Y61: 4 | AC61: Guidez L. | AJ61: DUD1 | AV61: J8 | BM61: =IF(AZ61="","",ROUNDDOWN(BF61/BJ61,3))
D63: J9 | H63: 45978 | N63: 13 | R63: 39 | U63: =IF(H63="","",ROUNDDOWN(N63/R63,3)) -> 0.333 | Y63: 3 | AC63: Lejeune F. | AJ63: DUD1 | AV63: J9 | BM63: =IF(AZ63="","",ROUNDDOWN(BF63/BJ63,3))
D65: J10 | H65: 45992 | N65: 15 | R65: 40 | U65: =IF(H65="","",ROUNDDOWN(N65/R65,3)) -> 0.375 | Y65: 3 | AC65: Engel G. | AJ65: DUD1 | AV65: J10 | BM65: =IF(AZ65="","",ROUNDDOWN(BF65/BJ65,3))
N67: =SUM(N47:Q66) -> 71 | U67: =IF(H67="","",ROUNDDOWN(N67/R67,3)) | BF67: =SUM(BF47:BI66) -> 115 | BM67: =IF(AZ67="","",ROUNDDOWN(BF67/BJ67,3))
H69: =IF(N67=0,"","Total") -> Total | N69: =IF(H69="","",SUM(N47:Q66)) -> 71 | R69: =IF(H69="","",SUM(R47:T66)) -> 199 | U69: =IF(H69="","",ROUNDDOWN(N69/R69,3)) -> 0.356 | AZ69: =IF(BF67=0,"","Total") -> Total | BF69: =IF(AZ69="","",SUM(BF47:BI66)) -> 115 | BJ69: =IF(AZ69="","",SUM(BJ47:BL66)) -> 198 | BM69: =IF(AZ69="","",ROUNDDOWN(BF69/BJ69,3)) -> 0.58
A112: Individuel Libre Match | AS112: Individuel Libre 1/4match | CK112: Individuel Handycap
H114: Date | N114: Pts | R114: Rep | U114: Moy. | Y114: Série | AC114: Advers. | AJ114: Equipe | AZ114: Date | BF114: Pts | BJ114: Rep | BM114: Moy. | BQ114: Série | BU114: Advers. | CB114: Equipe | CR114: Date | CX114: Pts | DB114: Rep | DE114: Moy. | DI114: Série | DM114: Advers. | DT114: Equipe
U116: =IF(H116="","",ROUNDDOWN(N116/R116,3)) | BM116: =IF(AZ116="","",ROUNDDOWN(BF116/BJ116,3)) | DE116: =IF(CR116="","",ROUNDDOWN(CX116/DB116,3))
U118: =IF(H118="","",ROUNDDOWN(N118/R118,3)) | BM118: =IF(AZ118="","",ROUNDDOWN(BF118/BJ118,3)) | DE118: =IF(CR118="","",ROUNDDOWN(CX118/DB118,3))
U120: =IF(H120="","",ROUNDDOWN(N120/R120,3)) | BM120: =IF(AZ120="","",ROUNDDOWN(BF120/BJ120,3)) | DE120: =IF(CR120="","",ROUNDDOWN(CX120/DB120,3))
U122: =IF(H122="","",ROUNDDOWN(N122/R122,3)) | BM122: =IF(AZ122="","",ROUNDDOWN(BF122/BJ122,3)) | DE122: =IF(CR122="","",ROUNDDOWN(CX122/DB122,3))
U124: =IF(H124="","",ROUNDDOWN(N124/R124,3)) | BM124: =IF(AZ124="","",ROUNDDOWN(BF124/BJ124,3)) | DE124: =IF(CR124="","",ROUNDDOWN(CX124/DB124,3))
U126: =IF(H126="","",ROUNDDOWN(N126/R126,3)) | BM126: =IF(AZ126="","",ROUNDDOWN(BF126/BJ126,3)) | DE126: =IF(CR126="","",ROUNDDOWN(CX126/DB126,3))
N128: =SUM(N116:Q127) -> 0 | U128: =IF(H128="","",ROUNDDOWN(N128/R128,3)) | BF128: =SUM(BF116:BI127) -> 0 | BM128: =IF(AZ128="","",ROUNDDOWN(BF128/BJ128,3)) | CX128: =SUM(CX116:DA127) -> 0 | DE128: =IF(CR128="","",ROUNDDOWN(CX128/DB128,3))
...

Sheet Bollini H.
A1: Bollini Hugues
H6: Catégorie | Y6: Libre | AO6: Cadre | BF6: 1bande | BW6: 3bandes Match | CM6: 3bandes 1/4match | DD6: 3bandes Match conv.
H8: Pts | L8: Rep | P8: Moy | Y8: =IF(N38="",0,N38)+IF(AD130="",0,AD130)+IF(BF130="",0,BF130)+IF(CX130="",0,CX130) -> 87 | AC8: =IF(R38="",0,R38)+IF(AG130="",0,AG130)+IF(BJ130="",0,BJ130)+IF(DB130="",0,DB130) -> 80 | AG8: =IF(Y8=0,0,ROUNDDOWN(Y8/AC8,3)) -> 1.087 | AO8: =IF(BF38="",0,BF38)+IF(AC153="",0,AC153)+IF(BF153="",0,BF153) -> 0 | AS8: =IF(BJ38="",0,BJ38)+IF(AG153="",0,AG153)+IF(BJ153="",0,BJ153) -> 0 | AW8: =IF(AO8=0,0,ROUNDDOWN(AO8/AS8,3)) -> 0 | BF8: =IF(CX153="",0,CX153)+IF(AC176="",0,AC176) -> 0 | BJ8: =IF(DB153="",0,DB153)+IF(AG176="",0,AG176) -> 0 | BN8: =IF(BF8=0,0,ROUNDDOWN(BF8/BJ8,3)) -> 0 | BW8: =IF(CX38="",0,CX38)+IF(N69="",0,N69)+IF(N199="",0,N199)+IF(BF199="",0,BF199)+IF(CX199="",0,CX199)+IF(BF176="",0,BF176) -> 0 | CA8: =IF(DB38="",0,DB38)+IF(R69="",0,R69)+IF(R199="",0,R199)+IF(BJ199="",0,BJ199)+IF(DB199="",0,DB199)+IF(BJ176="",0,BJ176) -> 0 | CE8: =IF(BW8=0,0,ROUNDDOWN(BW8/CA8,3)) -> 0 | CM8: =IF(BF69="",0,BF69)+IF(AD199="",0,AD199)+IF(BV199="",0,BV199)+IF(DN199="",0,DN199)+IF(CX176="",0,CX176) -> 0 | CQ8: =IF(BJ69="",0,BJ69)+IF(AG199="",0,AG199)+IF(BY199="",0,BY199)+IF(DQ199="",0,DQ199)+IF(DB176="",0,DB176) -> 0 | CU8: =IF(CM8=0,0,ROUNDDOWN(CM8/CQ8,3)) -> 0 | DD8: =SUM(BW8+(CM8*0.7)) -> 0 | DH8: =SUM(CA8+CQ8) -> 0 | DL8: =IF(DD8=0,0,ROUNDDOWN(DD8/DH8,3)) -> 0
A12: Libre | AS12: Cadre | CK12: 3bandes Billard Match
H14: Date | N14: Pts | R14: Rep | U14: Moy. | Y14: Série | AC14: Advers. | AJ14: Equipe | AZ14: Date | BF14: Pts | BJ14: Rep | BM14: Moy. | BQ14: Série | BU14: Advers. | CB14: Equipe | CR14: Date | CX14: Pts | DB14: Rep | DE14: Moy. | DI14: Série | DM14: Advers. | DT14: Equipe
A16: ITC Classique | D16: J 1 | U16: =IF(H16="","",ROUNDDOWN(N16/R16,3)) | AS16: ITC Classique | AV16: J 1 | BM16: =IF(AZ16="","",ROUNDDOWN(BF16/BJ16,3)) | CK16: ITC Classique | CN16: J 1 | DE16: =IF(CR16="","",ROUNDDOWN(CX16/DB16,3))
D18: J 2 | U18: =IF(H18="","",ROUNDDOWN(N18/R18,3)) | AV18: J 2 | BM18: =IF(AZ18="","",ROUNDDOWN(BF18/BJ18,3)) | CN18: J 2 | DE18: =IF(CR18="","",ROUNDDOWN(CX18/DB18,3))
D20: J 3 | H20: 46055 | N20: 28 | R20: 20 | U20: =IF(H20="","",ROUNDDOWN(N20/R20,3)) -> 1.4 | Y20: 5 | AC20: Fank F. | AJ20: DUD2 | AV20: J 3 | BM20: =IF(AZ20="","",ROUNDDOWN(BF20/BJ20,3)) | CN20: J 3 | DE20: =IF(CR20="","",ROUNDDOWN(CX20/DB20,3))
D22: J 4 | H22: 46062 | N22: 18 | R22: 20 | U22: =IF(H22="","",ROUNDDOWN(N22/R22,3)) -> 0.9 | Y22: 4 | AC22: Cruz J. | AJ22: DUD2 | AV22: J 4 | BM22: =IF(AZ22="","",ROUNDDOWN(BF22/BJ22,3)) | CN22: J 4 | DE22: =IF(CR22="","",ROUNDDOWN(CX22/DB22,3))
D24: J 5 | H24: 46076 | N24: 21 | R24: 20 | U24: =IF(H24="","",ROUNDDOWN(N24/R24,3)) -> 1.05 | Y24: 5 | AC24: Felix B. | AJ24: DUD2 | AV24: J 5 | BM24: =IF(AZ24="","",ROUNDDOWN(BF24/BJ24,3)) | CN24: J 5 | DE24: =IF(CR24="","",ROUNDDOWN(CX24/DB24,3))
D26: J 6 | H26: 46083 | N26: 20 | R26: 20 | U26: =IF(H26="","",ROUNDDOWN(N26/R26,3)) -> 1 | Y26: 3 | AC26: Soares A. | AJ26: DUD2 | AV26: J 6 | BM26: =IF(AZ26="","",ROUNDDOWN(BF26/BJ26,3)) | CN26: J 6 | DE26: =IF(CR26="","",ROUNDDOWN(CX26/DB26,3))
D28: J7 | U28: =IF(H28="","",ROUNDDOWN(N28/R28,3)) | AV28: J7 | BM28: =IF(AZ28="","",ROUNDDOWN(BF28/BJ28,3)) | CN28: J7 | DE28: =IF(CR28="","",ROUNDDOWN(CX28/DB28,3))
D30: J8 | U30: =IF(H30="","",ROUNDDOWN(N30/R30,3)) | AV30: J8 | BM30: =IF(AZ30="","",ROUNDDOWN(BF30/BJ30,3)) | CN30: J8 | DE30: =IF(CR30="","",ROUNDDOWN(CX30/DB30,3))
D32: J9 | U32: =IF(H32="","",ROUNDDOWN(N32/R32,3)) | AV32: J9 | BM32: =IF(AZ32="","",ROUNDDOWN(BF32/BJ32,3)) | CN32: J9 | DE32: =IF(CR32="","",ROUNDDOWN(CX32/DB32,3))
D34: J10 | U34: =IF(H34="","",ROUNDDOWN(N34/R34,3)) | AV34: J10 | BM34: =IF(AZ34="","",ROUNDDOWN(BF34/BJ34,3)) | CN34: J10 | DE34: =IF(CR34="","",ROUNDDOWN(CX34/DB34,3))
N36: =SUM(N16:Q35) -> 87 | U36: =IF(H36="","",ROUNDDOWN(N36/R36,3)) | BF36: =SUM(BF16:BI35) -> 0 | BM36: =IF(AZ36="","",ROUNDDOWN(BF36/BJ36,3)) | CX36: =SUM(CX16:DA35) -> 0 | DE36: =IF(CR36="","",ROUNDDOWN(CX36/DB36,3))
H38: =IF(N36=0,"","Total") -> Total | N38: =IF(H38="","",SUM(N16:Q35)) -> 87 | R38: =IF(H38="","",SUM(R16:T35)) -> 80 | U38: =IF(H38="","",ROUNDDOWN(N38/R38,3)) -> 1.087 | AZ38: =IF(BF36=0,"","Total") | BF38: =IF(AZ38="","",SUM(BF16:BI35)) | BJ38: =IF(AZ38="","",SUM(BJ16:BL35)) | BM38: =IF(AZ38="","",ROUNDDOWN(BF38/BJ38,3)) | CR38: =IF(CX36=0,"","Total") | CX38: =IF(CR38="","",SUM(CX16:DA35)) | DB38: =IF(CR38="","",SUM(DB16:DD35)) | DE38: =IF(CR38="","",ROUNDDOWN(CX38/DB38,3))
Z39: 2 Matchs pour moyenne
A43: 3bandes Billard Match | AS43: 3bandes Billard 1/4 match
H45: Date | N45: Pts | R45: Rep | U45: Moy. | Y45: Série | AC45: Advers. | AJ45: Equipe | AZ45: Date | BF45: Pts | BJ45: Rep | BM45: Moy. | BQ45: Série | BU45: Advers. | CB45: Equipe
A47: ITC 3bandes | D47: J 1 | U47: =IF(H47="","",ROUNDDOWN(N47/R47,3)) | AS47: ITC 3bandes | AV47: J 1 | BM47: =IF(AZ47="","",ROUNDDOWN(BF47/BJ47,3))
D49: J 2 | U49: =IF(H49="","",ROUNDDOWN(N49/R49,3)) | AV49: J 2 | BM49: =IF(AZ49="","",ROUNDDOWN(BF49/BJ49,3))
D51: J 3 | U51: =IF(H51="","",ROUNDDOWN(N51/R51,3)) | AV51: J 3 | BM51: =IF(AZ51="","",ROUNDDOWN(BF51/BJ51,3))
D53: J 4 | U53: =IF(H53="","",ROUNDDOWN(N53/R53,3)) | AV53: J 4 | BM53: =IF(AZ53="","",ROUNDDOWN(BF53/BJ53,3))
D55: J 5 | U55: =IF(H55="","",ROUNDDOWN(N55/R55,3)) | AV55: J 5 | BM55: =IF(AZ55="","",ROUNDDOWN(BF55/BJ55,3))
D57: J 6 | U57: =IF(H57="","",ROUNDDOWN(N57/R57,3)) | AV57: J 6 | BM57: =IF(AZ57="","",ROUNDDOWN(BF57/BJ57,3))
D59: J7 | U59: =IF(H59="","",ROUNDDOWN(N59/R59,3)) | AV59: J7 | BM59: =IF(AZ59="","",ROUNDDOWN(BF59/BJ59,3))
D61: J8 | U61: =IF(H61="","",ROUNDDOWN(N61/R61,3)) | AV61: J8 | BM61: =IF(AZ61="","",ROUNDDOWN(BF61/BJ61,3))
D63: J9 | U63: =IF(H63="","",ROUNDDOWN(N63/R63,3)) | AV63: J9 | BM63: =IF(AZ63="","",ROUNDDOWN(BF63/BJ63,3))
D65: J10 | U65: =IF(H65="","",ROUNDDOWN(N65/R65,3)) | AV65: J10 | BM65: =IF(AZ65="","",ROUNDDOWN(BF65/BJ65,3))
N67: =SUM(N47:Q66) -> 0 | U67: =IF(H67="","",ROUNDDOWN(N67/R67,3)) | BF67: =SUM(BF47:BI66) -> 0 | BM67: =IF(AZ67="","",ROUNDDOWN(BF67/BJ67,3))
H69: =IF(N67=0,"","Total") | N69: =IF(H69="","",SUM(N47:Q66)) | R69: =IF(H69="","",SUM(R47:T66)) | U69: =IF(H69="","",ROUNDDOWN(N69/R69,3)) | AZ69: =IF(BF67=0,"","Total") | BF69: =IF(AZ69="","",SUM(BF47:BI66)) | BJ69: =IF(AZ69="","",SUM(BJ47:BL66)) | BM69: =IF(AZ69="","",ROUNDDOWN(BF69/BJ69,3))
A112: Individuel Libre Match | AS112: Individuel Libre 1/4match | CK112: Individuel Handycap
H114: Date | N114: Pts | R114: Rep | U114: Moy. | Y114: Série | AC114: Advers. | AJ114: Equipe | AZ114: Date | BF114: Pts | BJ114: Rep | BM114: Moy. | BQ114: Série | BU114: Advers. | CB114: Equipe | CR114: Date | CX114: Pts | DB114: Rep | DE114: Moy. | DI114: Série | DM114: Advers. | DT114: Equipe
U116: =IF(H116="","",ROUNDDOWN(N116/R116,3)) | BM116: =IF(AZ116="","",ROUNDDOWN(BF116/BJ116,3)) | DE116: =IF(CR116="","",ROUNDDOWN(CX116/DB116,3))
U118: =IF(H118="","",ROUNDDOWN(N118/R118,3)) | BM118: =IF(AZ118="","",ROUNDDOWN(BF118/BJ118,3)) | DE118: =IF(CR118="","",ROUNDDOWN(CX118/DB118,3))
U120: =IF(H120="","",ROUNDDOWN(N120/R120,3)) | BM120: =IF(AZ120="","",ROUNDDOWN(BF120/BJ120,3)) | DE120: =IF(CR120="","",ROUNDDOWN(CX120/DB120,3))
U122: =IF(H122="","",ROUNDDOWN(N122/R122,3)) | BM122: =IF(AZ122="","",ROUNDDOWN(BF122/BJ122,3)) | DE122: =IF(CR122="","",ROUNDDOWN(CX122/DB122,3))
U124: =IF(H124="","",ROUNDDOWN(N124/R124,3)) | BM124: =IF(AZ124="","",ROUNDDOWN(BF124/BJ124,3)) | DE124: =IF(CR124="","",ROUNDDOWN(CX124/DB124,3))
U126: =IF(H126="","",ROUNDDOWN(N126/R126,3)) | BM126: =IF(AZ126="","",ROUNDDOWN(BF126/BJ126,3)) | DE126: =IF(CR126="","",ROUNDDOWN(CX126/DB126,3))
...

Sheet Bollini L.
A1: Bollini Lucas
H6: Catégorie | Y6: Libre | AO6: Cadre | BF6: 1bande | BW6: 3bandes Match | CM6: 3bandes 1/4match | DD6: 3bandes Match conv.
H8: Pts | L8: Rep | P8: Moy | Y8: =IF(N38="",0,N38)+IF(AD130="",0,AD130)+IF(BF130="",0,BF130)+IF(CX130="",0,CX130) -> 21 | AC8: =IF(R38="",0,R38)+IF(AG130="",0,AG130)+IF(BJ130="",0,BJ130)+IF(DB130="",0,DB130) -> 40 | AG8: =IF(Y8=0,0,ROUNDDOWN(Y8/AC8,3)) -> 0.525 | AO8: =IF(BF38="",0,BF38)+IF(AC153="",0,AC153)+IF(BF153="",0,BF153) -> 0 | AS8: =IF(BJ38="",0,BJ38)+IF(AG153="",0,AG153)+IF(BJ153="",0,BJ153) -> 0 | AW8: =IF(AO8=0,0,ROUNDDOWN(AO8/AS8,3)) -> 0 | BF8: =IF(CX153="",0,CX153)+IF(AC176="",0,AC176) -> 0 | BJ8: =IF(DB153="",0,DB153)+IF(AG176="",0,AG176) -> 0 | BN8: =IF(BF8=0,0,ROUNDDOWN(BF8/BJ8,3)) -> 0 | BW8: =IF(CX38="",0,CX38)+IF(N69="",0,N69)+IF(N199="",0,N199)+IF(BF199="",0,BF199)+IF(CX199="",0,CX199)+IF(BF176="",0,BF176) -> 0 | CA8: =IF(DB38="",0,DB38)+IF(R69="",0,R69)+IF(R199="",0,R199)+IF(BJ199="",0,BJ199)+IF(DB199="",0,DB199)+IF(BJ176="",0,BJ176) -> 0 | CE8: =IF(BW8=0,0,ROUNDDOWN(BW8/CA8,3)) -> 0 | CM8: =IF(BF69="",0,BF69)+IF(AD199="",0,AD199)+IF(BV199="",0,BV199)+IF(DN199="",0,DN199)+IF(CX176="",0,CX176) -> 0 | CQ8: =IF(BJ69="",0,BJ69)+IF(AG199="",0,AG199)+IF(BY199="",0,BY199)+IF(DQ199="",0,DQ199)+IF(DB176="",0,DB176) -> 0 | CU8: =IF(CM8=0,0,ROUNDDOWN(CM8/CQ8,3)) -> 0 | DD8: =SUM(BW8+(CM8*0.7)) -> 0 | DH8: =SUM(CA8+CQ8) -> 0 | DL8: =IF(DD8=0,0,ROUNDDOWN(DD8/DH8,3)) -> 0
A12: Libre | AS12: Cadre | CK12: 3bandes Billard Match
H14: Date | N14: Pts | R14: Rep | U14: Moy. | Y14: Série | AC14: Advers. | AJ14: Equipe | AZ14: Date | BF14: Pts | BJ14: Rep | BM14: Moy. | BQ14: Série | BU14: Advers. | CB14: Equipe | CR14: Date | CX14: Pts | DB14: Rep | DE14: Moy. | DI14: Série | DM14: Advers. | DT14: Equipe
A16: ITC Classique | D16: J 1 | U16: =IF(H16="","",ROUNDDOWN(N16/R16,3)) | AS16: ITC Classique | AV16: J 1 | BM16: =IF(AZ16="","",ROUNDDOWN(BF16/BJ16,3)) | CK16: ITC Classique | CN16: J 1 | DE16: =IF(CR16="","",ROUNDDOWN(CX16/DB16,3))
D18: J 2 | U18: =IF(H18="","",ROUNDDOWN(N18/R18,3)) | AV18: J 2 | BM18: =IF(AZ18="","",ROUNDDOWN(BF18/BJ18,3)) | CN18: J 2 | DE18: =IF(CR18="","",ROUNDDOWN(CX18/DB18,3))
D20: J 3 | U20: =IF(H20="","",ROUNDDOWN(N20/R20,3)) | AV20: J 3 | BM20: =IF(AZ20="","",ROUNDDOWN(BF20/BJ20,3)) | CN20: J 3 | DE20: =IF(CR20="","",ROUNDDOWN(CX20/DB20,3))
D22: J 4 | U22: =IF(H22="","",ROUNDDOWN(N22/R22,3)) | AV22: J 4 | BM22: =IF(AZ22="","",ROUNDDOWN(BF22/BJ22,3)) | CN22: J 4 | DE22: =IF(CR22="","",ROUNDDOWN(CX22/DB22,3))
D24: J 5 | H24: 46076 | N24: 10 | R24: 20 | U24: =IF(H24="","",ROUNDDOWN(N24/R24,3)) -> 0.5 | Y24: 2 | AC24: Pierre P. | AJ24: DUD2 | AV24: J 5 | BM24: =IF(AZ24="","",ROUNDDOWN(BF24/BJ24,3)) | CN24: J 5 | DE24: =IF(CR24="","",ROUNDDOWN(CX24/DB24,3))
D26: J 6 | H26: 46083 | N26: 11 | R26: 20 | U26: =IF(H26="","",ROUNDDOWN(N26/R26,3)) -> 0.55 | Y26: 5 | AC26: Barison R. | AJ26: DUD2 | AV26: J 6 | BM26: =IF(AZ26="","",ROUNDDOWN(BF26/BJ26,3)) | CN26: J 6 | DE26: =IF(CR26="","",ROUNDDOWN(CX26/DB26,3))
D28: J7 | U28: =IF(H28="","",ROUNDDOWN(N28/R28,3)) | AV28: J7 | BM28: =IF(AZ28="","",ROUNDDOWN(BF28/BJ28,3)) | CN28: J7 | DE28: =IF(CR28="","",ROUNDDOWN(CX28/DB28,3))
D30: J8 | U30: =IF(H30="","",ROUNDDOWN(N30/R30,3)) | AV30: J8 | BM30: =IF(AZ30="","",ROUNDDOWN(BF30/BJ30,3)) | CN30: J8 | DE30: =IF(CR30="","",ROUNDDOWN(CX30/DB30,3))
D32: J9 | U32: =IF(H32="","",ROUNDDOWN(N32/R32,3)) | AV32: J9 | BM32: =IF(AZ32="","",ROUNDDOWN(BF32/BJ32,3)) | CN32: J9 | DE32: =IF(CR32="","",ROUNDDOWN(CX32/DB32,3))
D34: J10 | U34: =IF(H34="","",ROUNDDOWN(N34/R34,3)) | AV34: J10 | BM34: =IF(AZ34="","",ROUNDDOWN(BF34/BJ34,3)) | CN34: J10 | DE34: =IF(CR34="","",ROUNDDOWN(CX34/DB34,3))
N36: =SUM(N16:Q35) -> 21 | U36: =IF(H36="","",ROUNDDOWN(N36/R36,3)) | BF36: =SUM(BF16:BI35) -> 0 | BM36: =IF(AZ36="","",ROUNDDOWN(BF36/BJ36,3)) | CX36: =SUM(CX16:DA35) -> 0 | DE36: =IF(CR36="","",ROUNDDOWN(CX36/DB36,3))
H38: =IF(N36=0,"","Total") -> Total | N38: =IF(H38="","",SUM(N16:Q35)) -> 21 | R38: =IF(H38="","",SUM(R16:T35)) -> 40 | U38: =IF(H38="","",ROUNDDOWN(N38/R38,3)) -> 0.525 | AZ38: =IF(BF36=0,"","Total") | BF38: =IF(AZ38="","",SUM(BF16:BI35)) | BJ38: =IF(AZ38="","",SUM(BJ16:BL35)) | BM38: =IF(AZ38="","",ROUNDDOWN(BF38/BJ38,3)) | CR38: =IF(CX36=0,"","Total") | CX38: =IF(CR38="","",SUM(CX16:DA35)) | DB38: =IF(CR38="","",SUM(DB16:DD35)) | DE38: =IF(CR38="","",ROUNDDOWN(CX38/DB38,3))
Z39: 2 Matchs pour moyenne
A43: 3bandes Billard Match | AS43: 3bandes Billard 1/4 match
H45: Date | N45: Pts | R45: Rep | U45: Moy. | Y45: Série | AC45: Advers. | AJ45: Equipe | AZ45: Date | BF45: Pts | BJ45: Rep | BM45: Moy. | BQ45: Série | BU45: Advers. | CB45: Equipe
A47: ITC 3bandes | D47: J 1 | U47: =IF(H47="","",ROUNDDOWN(N47/R47,3)) | AS47: ITC 3bandes | AV47: J 1 | BM47: =IF(AZ47="","",ROUNDDOWN(BF47/BJ47,3))
D49: J 2 | U49: =IF(H49="","",ROUNDDOWN(N49/R49,3)) | AV49: J 2 | BM49: =IF(AZ49="","",ROUNDDOWN(BF49/BJ49,3))
D51: J 3 | U51: =IF(H51="","",ROUNDDOWN(N51/R51,3)) | AV51: J 3 | BM51: =IF(AZ51="","",ROUNDDOWN(BF51/BJ51,3))
D53: J 4 | U53: =IF(H53="","",ROUNDDOWN(N53/R53,3)) | AV53: J 4 | BM53: =IF(AZ53="","",ROUNDDOWN(BF53/BJ53,3))
D55: J 5 | U55: =IF(H55="","",ROUNDDOWN(N55/R55,3)) | AV55: J 5 | BM55: =IF(AZ55="","",ROUNDDOWN(BF55/BJ55,3))
D57: J 6 | U57: =IF(H57="","",ROUNDDOWN(N57/R57,3)) | AV57: J 6 | BM57: =IF(AZ57="","",ROUNDDOWN(BF57/BJ57,3))
D59: J7 | U59: =IF(H59="","",ROUNDDOWN(N59/R59,3)) | AV59: J7 | BM59: =IF(AZ59="","",ROUNDDOWN(BF59/BJ59,3))
D61: J8 | U61: =IF(H61="","",ROUNDDOWN(N61/R61,3)) | AV61: J8 | BM61: =IF(AZ61="","",ROUNDDOWN(BF61/BJ61,3))
D63: J9 | U63: =IF(H63="","",ROUNDDOWN(N63/R63,3)) | AV63: J9 | BM63: =IF(AZ63="","",ROUNDDOWN(BF63/BJ63,3))
D65: J10 | U65: =IF(H65="","",ROUNDDOWN(N65/R65,3)) | AV65: J10 | BM65: =IF(AZ65="","",ROUNDDOWN(BF65/BJ65,3))
N67: =SUM(N47:Q66) -> 0 | U67: =IF(H67="","",ROUNDDOWN(N67/R67,3)) | BF67: =SUM(BF47:BI66) -> 0 | BM67: =IF(AZ67="","",ROUNDDOWN(BF67/BJ67,3))
H69: =IF(N67=0,"","Total") | N69: =IF(H69="","",SUM(N47:Q66)) | R69: =IF(H69="","",SUM(R47:T66)) | U69: =IF(H69="","",ROUNDDOWN(N69/R69,3)) | AZ69: =IF(BF67=0,"","Total") | BF69: =IF(AZ69="","",SUM(BF47:BI66)) | BJ69: =IF(AZ69="","",SUM(BJ47:BL66)) | BM69: =IF(AZ69="","",ROUNDDOWN(BF69/BJ69,3))
A112: Individuel Libre Match | AS112: Individuel Libre 1/4match | CK112: Individuel Handycap
H114: Date | N114: Pts | R114: Rep | U114: Moy. | Y114: Série | AC114: Advers. | AJ114: Equipe | AZ114: Date | BF114: Pts | BJ114: Rep | BM114: Moy. | BQ114: Série | BU114: Advers. | CB114: Equipe | CR114: Date | CX114: Pts | DB114: Rep | DE114: Moy. | DI114: Série | DM114: Advers. | DT114: Equipe
U116: =IF(H116="","",ROUNDDOWN(N116/R116,3)) | BM116: =IF(AZ116="","",ROUNDDOWN(BF116/BJ116,3)) | DE116: =IF(CR116="","",ROUNDDOWN(CX116/DB116,3))
U118: =IF(H118="","",ROUNDDOWN(N118/R118,3)) | BM118: =IF(AZ118="","",ROUNDDOWN(BF118/BJ118,3)) | DE118: =IF(CR118="","",ROUNDDOWN(CX118/DB118,3))
U120: =IF(H120="","",ROUNDDOWN(N120/R120,3)) | BM120: =IF(AZ120="","",ROUNDDOWN(BF120/BJ120,3)) | DE120: =IF(CR120="","",ROUNDDOWN(CX120/DB120,3))
U122: =IF(H122="","",ROUNDDOWN(N122/R122,3)) | BM122: =IF(AZ122="","",ROUNDDOWN(BF122/BJ122,3)) | DE122: =IF(CR122="","",ROUNDDOWN(CX122/DB122,3))
U124: =IF(H124="","",ROUNDDOWN(N124/R124,3)) | BM124: =IF(AZ124="","",ROUNDDOWN(BF124/BJ124,3)) | DE124: =IF(CR124="","",ROUNDDOWN(CX124/DB124,3))
U126: =IF(H126="","",ROUNDDOWN(N126/R126,3)) | BM126: =IF(AZ126="","",ROUNDDOWN(BF126/BJ126,3)) | DE126: =IF(CR126="","",ROUNDDOWN(CX126/DB126,3))
...

Sheet Borneque
A1: Borneque Fabrice
H6: Catégorie | Y6: Libre | AO6: Cadre | BF6: 1bande | BW6: 3bandes Match | CM6: 3bandes 1/4match | DD6: 3bandes Match conv.
H8: Pts | L8: Rep | P8: Moy | Y8: =IF(N38="",0,N38)+IF(AD130="",0,AD130)+IF(BF130="",0,BF130)+IF(CX130="",0,CX130) -> 0 | AC8: =IF(R38="",0,R38)+IF(AG130="",0,AG130)+IF(BJ130="",0,BJ130)+IF(DB130="",0,DB130) -> 0 | AG8: =IF(Y8=0,0,ROUNDDOWN(Y8/AC8,3)) -> 0 | AO8: =IF(BF38="",0,BF38)+IF(AC153="",0,AC153)+IF(BF153="",0,BF153) -> 0 | AS8: =IF(BJ38="",0,BJ38)+IF(AG153="",0,AG153)+IF(BJ153="",0,BJ153) -> 0 | AW8: =IF(AO8=0,0,ROUNDDOWN(AO8/AS8,3)) -> 0 | BF8: =IF(CX153="",0,CX153)+IF(AC176="",0,AC176) -> 0 | BJ8: =IF(DB153="",0,DB153)+IF(AG176="",0,AG176) -> 0 | BN8: =IF(BF8=0,0,ROUNDDOWN(BF8/BJ8,3)) -> 0 | BW8: =IF(CX38="",0,CX38)+IF(N69="",0,N69)+IF(N199="",0,N199)+IF(BF199="",0,BF199)+IF(CX199="",0,CX199)+IF(BF176="",0,BF176) -> 50 | CA8: =IF(DB38="",0,DB38)+IF(R69="",0,R69)+IF(R199="",0,R199)+IF(BJ199="",0,BJ199)+IF(DB199="",0,DB199)+IF(BJ176="",0,BJ176) -> 280 | CE8: =IF(BW8=0,0,ROUNDDOWN(BW8/CA8,3)) -> 0.178 | CM8: =IF(BF69="",0,BF69)+IF(AD199="",0,AD199)+IF(BV199="",0,BV199)+IF(DN199="",0,DN199)+IF(CX176="",0,CX176) -> 21 | CQ8: =IF(BJ69="",0,BJ69)+IF(AG199="",0,AG199)+IF(BY199="",0,BY199)+IF(DQ199="",0,DQ199)+IF(DB176="",0,DB176) -> 97 | CU8: =IF(CM8=0,0,ROUNDDOWN(CM8/CQ8,3)) -> 0.216 | DD8: =SUM(BW8+(CM8*0.7)) -> 64.7 | DH8: =SUM(CA8+CQ8) -> 377 | DL8: =IF(DD8=0,0,ROUNDDOWN(DD8/DH8,3)) -> 0.171
A12: Libre | AS12: Cadre | CK12: 3bandes Billard Match
H14: Date | N14: Pts | R14: Rep | U14: Moy. | Y14: Série | AC14: Advers. | AJ14: Equipe | AZ14: Date | BF14: Pts | BJ14: Rep | BM14: Moy. | BQ14: Série | BU14: Advers. | CB14: Equipe | CR14: Date | CX14: Pts | DB14: Rep | DE14: Moy. | DI14: Série | DM14: Advers. | DT14: Equipe
A16: ITC Classique | D16: J 1 | U16: =IF(H16="","",ROUNDDOWN(N16/R16,3)) | AS16: ITC Classique | AV16: J 1 | BM16: =IF(AZ16="","",ROUNDDOWN(BF16/BJ16,3)) | CK16: ITC Classique | CN16: J 1 | CR16: 46041 | CX16: 6 | DB16: 40 | DE16: =IF(CR16="","",ROUNDDOWN(CX16/DB16,3)) -> 0.15 | DI16: 1 | DM16: Biver R. | DT16: DUD2
D18: J 2 | U18: =IF(H18="","",ROUNDDOWN(N18/R18,3)) | AV18: J 2 | BM18: =IF(AZ18="","",ROUNDDOWN(BF18/BJ18,3)) | CN18: J 2 | CR18: 46048 | CX18: 6 | DB18: 40 | DE18: =IF(CR18="","",ROUNDDOWN(CX18/DB18,3)) -> 0.15 | DI18: 2 | DM18: Lejeune F. | DT18: DUD2
D20: J 3 | U20: =IF(H20="","",ROUNDDOWN(N20/R20,3)) | AV20: J 3 | BM20: =IF(AZ20="","",ROUNDDOWN(BF20/BJ20,3)) | CN20: J 3 | DE20: =IF(CR20="","",ROUNDDOWN(CX20/DB20,3))
D22: J 4 | U22: =IF(H22="","",ROUNDDOWN(N22/R22,3)) | AV22: J 4 | BM22: =IF(AZ22="","",ROUNDDOWN(BF22/BJ22,3)) | CN22: J 4 | DE22: =IF(CR22="","",ROUNDDOWN(CX22/DB22,3))
D24: J 5 | U24: =IF(H24="","",ROUNDDOWN(N24/R24,3)) | AV24: J 5 | BM24: =IF(AZ24="","",ROUNDDOWN(BF24/BJ24,3)) | CN24: J 5 | DE24: =IF(CR24="","",ROUNDDOWN(CX24/DB24,3))
D26: J 6 | U26: =IF(H26="","",ROUNDDOWN(N26/R26,3)) | AV26: J 6 | BM26: =IF(AZ26="","",ROUNDDOWN(BF26/BJ26,3)) | CN26: J 6 | DE26: =IF(CR26="","",ROUNDDOWN(CX26/DB26,3))
D28: J7 | U28: =IF(H28="","",ROUNDDOWN(N28/R28,3)) | AV28: J7 | BM28: =IF(AZ28="","",ROUNDDOWN(BF28/BJ28,3)) | CN28: J7 | DE28: =IF(CR28="","",ROUNDDOWN(CX28/DB28,3))
D30: J8 | U30: =IF(H30="","",ROUNDDOWN(N30/R30,3)) | AV30: J8 | BM30: =IF(AZ30="","",ROUNDDOWN(BF30/BJ30,3)) | CN30: J8 | DE30: =IF(CR30="","",ROUNDDOWN(CX30/DB30,3))
D32: J9 | U32: =IF(H32="","",ROUNDDOWN(N32/R32,3)) | AV32: J9 | BM32: =IF(AZ32="","",ROUNDDOWN(BF32/BJ32,3)) | CN32: J9 | DE32: =IF(CR32="","",ROUNDDOWN(CX32/DB32,3))
D34: J10 | U34: =IF(H34="","",ROUNDDOWN(N34/R34,3)) | AV34: J10 | BM34: =IF(AZ34="","",ROUNDDOWN(BF34/BJ34,3)) | CN34: J10 | DE34: =IF(CR34="","",ROUNDDOWN(CX34/DB34,3))
N36: =SUM(N16:Q35) -> 0 | U36: =IF(H36="","",ROUNDDOWN(N36/R36,3)) | BF36: =SUM(BF16:BI35) -> 0 | BM36: =IF(AZ36="","",ROUNDDOWN(BF36/BJ36,3)) | CX36: =SUM(CX16:DA35) -> 12 | DE36: =IF(CR36="","",ROUNDDOWN(CX36/DB36,3))
H38: =IF(N36=0,"","Total") | N38: =IF(H38="","",SUM(N16:Q35)) | R38: =IF(H38="","",SUM(R16:T35)) | U38: =IF(H38="","",ROUNDDOWN(N38/R38,3)) | AZ38: =IF(BF36=0,"","Total") | BF38: =IF(AZ38="","",SUM(BF16:BI35)) | BJ38: =IF(AZ38="","",SUM(BJ16:BL35)) | BM38: =IF(AZ38="","",ROUNDDOWN(BF38/BJ38,3)) | CR38: =IF(CX36=0,"","Total") -> Total | CX38: =IF(CR38="","",SUM(CX16:DA35)) -> 12 | DB38: =IF(CR38="","",SUM(DB16:DD35)) -> 80 | DE38: =IF(CR38="","",ROUNDDOWN(CX38/DB38,3)) -> 0.15
A43: 3bandes Billard Match | AS43: 3bandes Billard 1/4 match
H45: Date | N45: Pts | R45: Rep | U45: Moy. | Y45: Série | AC45: Advers. | AJ45: Equipe | AZ45: Date | BF45: Pts | BJ45: Rep | BM45: Moy. | BQ45: Série | BU45: Advers. | CB45: Equipe
A47: ITC 3bandes | D47: J 1 | U47: =IF(H47="","",ROUNDDOWN(N47/R47,3)) | AS47: ITC 3bandes | AV47: J 1 | BM47: =IF(AZ47="","",ROUNDDOWN(BF47/BJ47,3))
D49: J 2 | U49: =IF(H49="","",ROUNDDOWN(N49/R49,3)) | AV49: J 2 | BM49: =IF(AZ49="","",ROUNDDOWN(BF49/BJ49,3))
D51: J 3 | U51: =IF(H51="","",ROUNDDOWN(N51/R51,3)) | AV51: J 3 | BM51: =IF(AZ51="","",ROUNDDOWN(BF51/BJ51,3))
D53: J 4 | U53: =IF(H53="","",ROUNDDOWN(N53/R53,3)) | AV53: J 4 | BM53: =IF(AZ53="","",ROUNDDOWN(BF53/BJ53,3))
D55: J 5 | U55: =IF(H55="","",ROUNDDOWN(N55/R55,3)) | AV55: J 5 | BM55: =IF(AZ55="","",ROUNDDOWN(BF55/BJ55,3))
D57: J 6 | U57: =IF(H57="","",ROUNDDOWN(N57/R57,3)) | AV57: J 6 | BM57: =IF(AZ57="","",ROUNDDOWN(BF57/BJ57,3))
D59: J7 | U59: =IF(H59="","",ROUNDDOWN(N59/R59,3)) | AV59: J7 | BM59: =IF(AZ59="","",ROUNDDOWN(BF59/BJ59,3))
D61: J8 | U61: =IF(H61="","",ROUNDDOWN(N61/R61,3)) | AV61: J8 | BM61: =IF(AZ61="","",ROUNDDOWN(BF61/BJ61,3))
D63: J9 | H63: 45978 | N63: 6 | R63: 40 | U63: =IF(H63="","",ROUNDDOWN(N63/R63,3)) -> 0.15 | Y63: 2 | AC63: Cruz J. | AJ63: DUD2 | AV63: J9 | BM63: =IF(AZ63="","",ROUNDDOWN(BF63/BJ63,3))
D65: J10 | U65: =IF(H65="","",ROUNDDOWN(N65/R65,3)) | AV65: J10 | AZ65: 45992 | BF65: 13 | BJ65: 40 | BM65: =IF(AZ65="","",ROUNDDOWN(BF65/BJ65,3)) -> 0.325 | BQ65: 2 | BU65: D'Hoest F. | CB65: DUD2
N67: =SUM(N47:Q66) -> 6 | U67: =IF(H67="","",ROUNDDOWN(N67/R67,3)) | BF67: =SUM(BF47:BI66) -> 13 | BM67: =IF(AZ67="","",ROUNDDOWN(BF67/BJ67,3))
H69: =IF(N67=0,"","Total") -> Total | N69: =IF(H69="","",SUM(N47:Q66)) -> 6 | R69: =IF(H69="","",SUM(R47:T66)) -> 40 | U69: =IF(H69="","",ROUNDDOWN(N69/R69,3)) -> 0.15 | AZ69: =IF(BF67=0,"","Total") -> Total | BF69: =IF(AZ69="","",SUM(BF47:BI66)) -> 13 | BJ69: =IF(AZ69="","",SUM(BJ47:BL66)) -> 40 | BM69: =IF(AZ69="","",ROUNDDOWN(BF69/BJ69,3)) -> 0.325
A112: Individuel Libre Match | AS112: Individuel Libre 1/4match | CK112: Individuel Handycap
H114: Date | N114: Pts | R114: Rep | U114: Moy. | Y114: Série | AC114: Advers. | AJ114: Equipe | AZ114: Date | BF114: Pts | BJ114: Rep | BM114: Moy. | BQ114: Série | BU114: Advers. | CB114: Equipe | CR114: Date | CX114: Pts | DB114: Rep | DE114: Moy. | DI114: Série | DM114: Advers. | DT114: Equipe
U116: =IF(H116="","",ROUNDDOWN(N116/R116,3)) | BM116: =IF(AZ116="","",ROUNDDOWN(BF116/BJ116,3)) | DE116: =IF(CR116="","",ROUNDDOWN(CX116/DB116,3))
U118: =IF(H118="","",ROUNDDOWN(N118/R118,3)) | BM118: =IF(AZ118="","",ROUNDDOWN(BF118/BJ118,3)) | DE118: =IF(CR118="","",ROUNDDOWN(CX118/DB118,3))
U120: =IF(H120="","",ROUNDDOWN(N120/R120,3)) | BM120: =IF(AZ120="","",ROUNDDOWN(BF120/BJ120,3)) | DE120: =IF(CR120="","",ROUNDDOWN(CX120/DB120,3))
U122: =IF(H122="","",ROUNDDOWN(N122/R122,3)) | BM122: =IF(AZ122="","",ROUNDDOWN(BF122/BJ122,3)) | DE122: =IF(CR122="","",ROUNDDOWN(CX122/DB122,3))
U124: =IF(H124="","",ROUNDDOWN(N124/R124,3)) | BM124: =IF(AZ124="","",ROUNDDOWN(BF124/BJ124,3)) | DE124: =IF(CR124="","",ROUNDDOWN(CX124/DB124,3))
U126: =IF(H126="","",ROUNDDOWN(N126/R126,3)) | BM126: =IF(AZ126="","",ROUNDDOWN(BF126/BJ126,3)) | DE126: =IF(CR126="","",ROUNDDOWN(CX126/DB126,3))
N128: =SUM(N116:Q127) -> 0 | U128: =IF(H128="","",ROUNDDOWN(N128/R128,3)) | BF128: =SUM(BF116:BI127) -> 0 | BM128: =IF(AZ128="","",ROUNDDOWN(BF128/BJ128,3)) | CX128: =SUM(CX116:DA127) -> 0 | DE128: =IF(CR128="","",ROUNDDOWN(CX128/DB128,3))
...

Sheet De Matos
A1: De Matos Ricardo
H6: Catégorie | Y6: Libre | AO6: Cadre | BF6: 1bande | BW6: 3bandes Match | CM6: 3bandes 1/4match | DD6: 3bandes Match conv.
H8: Pts | L8: Rep | P8: Moy | Y8: =IF(N38="",0,N38)+IF(AD130="",0,AD130)+IF(BF130="",0,BF130)+IF(CX130="",0,CX130) -> 29 | AC8: =IF(R38="",0,R38)+IF(AG130="",0,AG130)+IF(BJ130="",0,BJ130)+IF(DB130="",0,DB130) -> 20 | AG8: =IF(Y8=0,0,ROUNDDOWN(Y8/AC8,3)) -> 1.45 | AO8: =IF(BF38="",0,BF38)+IF(AC153="",0,AC153)+IF(BF153="",0,BF153) -> 0 | AS8: =IF(BJ38="",0,BJ38)+IF(AG153="",0,AG153)+IF(BJ153="",0,BJ153) -> 0 | AW8: =IF(AO8=0,0,ROUNDDOWN(AO8/AS8,3)) -> 0 | BF8: =IF(CX153="",0,CX153)+IF(AC176="",0,AC176) -> 0 | BJ8: =IF(DB153="",0,DB153)+IF(AG176="",0,AG176) -> 0 | BN8: =IF(BF8=0,0,ROUNDDOWN(BF8/BJ8,3)) -> 0 | BW8: =IF(CX38="",0,CX38)+IF(N69="",0,N69)+IF(N199="",0,N199)+IF(BF199="",0,BF199)+IF(CX199="",0,CX199)+IF(BF176="",0,BF176) -> 42 | CA8: =IF(DB38="",0,DB38)+IF(R69="",0,R69)+IF(R199="",0,R199)+IF(BJ199="",0,BJ199)+IF(DB199="",0,DB199)+IF(BJ176="",0,BJ176) -> 240 | CE8: =IF(BW8=0,0,ROUNDDOWN(BW8/CA8,3)) -> 0.175 | CM8: =IF(BF69="",0,BF69)+IF(AD199="",0,AD199)+IF(BV199="",0,BV199)+IF(DN199="",0,DN199)+IF(CX176="",0,CX176) -> 35 | CQ8: =IF(BJ69="",0,BJ69)+IF(AG199="",0,AG199)+IF(BY199="",0,BY199)+IF(DQ199="",0,DQ199)+IF(DB176="",0,DB176) -> 120 | CU8: =IF(CM8=0,0,ROUNDDOWN(CM8/CQ8,3)) -> 0.291 | DD8: =SUM(BW8+(CM8*0.7)) -> 66.5 | DH8: =SUM(CA8+CQ8) -> 360 | DL8: =IF(DD8=0,0,ROUNDDOWN(DD8/DH8,3)) -> 0.184
A12: Libre | AS12: Cadre | CK12: 3bandes Billard Match
H14: Date | N14: Pts | R14: Rep | U14: Moy. | Y14: Série | AC14: Advers. | AJ14: Equipe | AZ14: Date | BF14: Pts | BJ14: Rep | BM14: Moy. | BQ14: Série | BU14: Advers. | CB14: Equipe | CR14: Date | CX14: Pts | DB14: Rep | DE14: Moy. | DI14: Série | DM14: Advers. | DT14: Equipe
A16: ITC Classique | D16: J 1 | H16: 46041 | N16: 29 | R16: 20 | U16: =IF(H16="","",ROUNDDOWN(N16/R16,3)) -> 1.45 | Y16: 5 | AC16: Pallucca C. | AJ16: DUD2 | AS16: ITC Classique | AV16: J 1 | BM16: =IF(AZ16="","",ROUNDDOWN(BF16/BJ16,3)) | CK16: ITC Classique | CN16: J 1 | DE16: =IF(CR16="","",ROUNDDOWN(CX16/DB16,3))
D18: J 2 | U18: =IF(H18="","",ROUNDDOWN(N18/R18,3)) | AV18: J 2 | BM18: =IF(AZ18="","",ROUNDDOWN(BF18/BJ18,3)) | CN18: J 2 | DE18: =IF(CR18="","",ROUNDDOWN(CX18/DB18,3))
D20: J 3 | U20: =IF(H20="","",ROUNDDOWN(N20/R20,3)) | AV20: J 3 | BM20: =IF(AZ20="","",ROUNDDOWN(BF20/BJ20,3)) | CN20: J 3 | DE20: =IF(CR20="","",ROUNDDOWN(CX20/DB20,3))
D22: J 4 | U22: =IF(H22="","",ROUNDDOWN(N22/R22,3)) | AV22: J 4 | BM22: =IF(AZ22="","",ROUNDDOWN(BF22/BJ22,3)) | CN22: J 4 | DE22: =IF(CR22="","",ROUNDDOWN(CX22/DB22,3))
D24: J 5 | U24: =IF(H24="","",ROUNDDOWN(N24/R24,3)) | AV24: J 5 | BM24: =IF(AZ24="","",ROUNDDOWN(BF24/BJ24,3)) | CN24: J 5 | DE24: =IF(CR24="","",ROUNDDOWN(CX24/DB24,3))
D26: J 6 | U26: =IF(H26="","",ROUNDDOWN(N26/R26,3)) | AV26: J 6 | BM26: =IF(AZ26="","",ROUNDDOWN(BF26/BJ26,3)) | CN26: J 6 | DE26: =IF(CR26="","",ROUNDDOWN(CX26/DB26,3))
D28: J7 | U28: =IF(H28="","",ROUNDDOWN(N28/R28,3)) | AV28: J7 | BM28: =IF(AZ28="","",ROUNDDOWN(BF28/BJ28,3)) | CN28: J7 | DE28: =IF(CR28="","",ROUNDDOWN(CX28/DB28,3))
D30: J8 | U30: =IF(H30="","",ROUNDDOWN(N30/R30,3)) | AV30: J8 | BM30: =IF(AZ30="","",ROUNDDOWN(BF30/BJ30,3)) | CN30: J8 | DE30: =IF(CR30="","",ROUNDDOWN(CX30/DB30,3))
D32: J9 | U32: =IF(H32="","",ROUNDDOWN(N32/R32,3)) | AV32: J9 | BM32: =IF(AZ32="","",ROUNDDOWN(BF32/BJ32,3)) | CN32: J9 | DE32: =IF(CR32="","",ROUNDDOWN(CX32/DB32,3))
D34: J10 | U34: =IF(H34="","",ROUNDDOWN(N34/R34,3)) | AV34: J10 | BM34: =IF(AZ34="","",ROUNDDOWN(BF34/BJ34,3)) | CN34: J10 | DE34: =IF(CR34="","",ROUNDDOWN(CX34/DB34,3))
N36: =SUM(N16:Q35) -> 29 | U36: =IF(H36="","",ROUNDDOWN(N36/R36,3)) | BF36: =SUM(BF16:BI35) -> 0 | BM36: =IF(AZ36="","",ROUNDDOWN(BF36/BJ36,3)) | CX36: =SUM(CX16:DA35) -> 0 | DE36: =IF(CR36="","",ROUNDDOWN(CX36/DB36,3))
H38: =IF(N36=0,"","Total") -> Total | N38: =IF(H38="","",SUM(N16:Q35)) -> 29 | R38: =IF(H38="","",SUM(R16:T35)) -> 20 | U38: =IF(H38="","",ROUNDDOWN(N38/R38,3)) -> 1.45 | AZ38: =IF(BF36=0,"","Total") | BF38: =IF(AZ38="","",SUM(BF16:BI35)) | BJ38: =IF(AZ38="","",SUM(BJ16:BL35)) | BM38: =IF(AZ38="","",ROUNDDOWN(BF38/BJ38,3)) | CR38: =IF(CX36=0,"","Total") | CX38: =IF(CR38="","",SUM(CX16:DA35)) | DB38: =IF(CR38="","",SUM(DB16:DD35)) | DE38: =IF(CR38="","",ROUNDDOWN(CX38/DB38,3))
A43: 3bandes Billard Match | AS43: 3bandes Billard 1/4 match
H45: Date | N45: Pts | R45: Rep | U45: Moy. | Y45: Série | AC45: Advers. | AJ45: Equipe | AZ45: Date | BF45: Pts | BJ45: Rep | BM45: Moy. | BQ45: Série | BU45: Advers. | CB45: Equipe
A47: ITC 3bandes | D47: J 1 | U47: =IF(H47="","",ROUNDDOWN(N47/R47,3)) | AS47: ITC 3bandes | AV47: J 1 | BM47: =IF(AZ47="","",ROUNDDOWN(BF47/BJ47,3))
D49: J 2 | U49: =IF(H49="","",ROUNDDOWN(N49/R49,3)) | AV49: J 2 | BM49: =IF(AZ49="","",ROUNDDOWN(BF49/BJ49,3))
D51: J 3 | U51: =IF(H51="","",ROUNDDOWN(N51/R51,3)) | AV51: J 3 | AZ51: 45929 | BF51: 11 | BJ51: 40 | BM51: =IF(AZ51="","",ROUNDDOWN(BF51/BJ51,3)) -> 0.275 | BQ51: 3 | BU51: Jeronimo J. | CB51: DUD2
D53: J 4 | U53: =IF(H53="","",ROUNDDOWN(N53/R53,3)) | AV53: J 4 | AZ53: 45936 | BF53: 17 | BJ53: 40 | BM53: =IF(AZ53="","",ROUNDDOWN(BF53/BJ53,3)) -> 0.425 | BQ53: 4 | BU53: Gül A. | CB53: DUD2
D55: J 5 | U55: =IF(H55="","",ROUNDDOWN(N55/R55,3)) | AV55: J 5 | BM55: =IF(AZ55="","",ROUNDDOWN(BF55/BJ55,3))
D57: J 6 | H57: 45950 | N57: 8 | R57: 40 | U57: =IF(H57="","",ROUNDDOWN(N57/R57,3)) -> 0.2 | Y57: 3 | AC57: Biver R. | AJ57: DUD2 | AV57: J 6 | BM57: =IF(AZ57="","",ROUNDDOWN(BF57/BJ57,3))
D59: J7 | H59: 45957 | N59: 4 | R59: 40 | U59: =IF(H59="","",ROUNDDOWN(N59/R59,3)) -> 0.1 | Y59: 1 | AC59: Lejeune F. | AJ59: DUD2 | AV59: J7 | BM59: =IF(AZ59="","",ROUNDDOWN(BF59/BJ59,3))
D61: J8 | U61: =IF(H61="","",ROUNDDOWN(N61/R61,3)) | AV61: J8 | AZ61: 45971 | BF61: 7 | BJ61: 40 | BM61: =IF(AZ61="","",ROUNDDOWN(BF61/BJ61,3)) -> 0.175 | BQ61: 2 | BU61: Jeronimo J. | CB61: DUD2
D63: J9 | U63: =IF(H63="","",ROUNDDOWN(N63/R63,3)) | AV63: J9 | BM63: =IF(AZ63="","",ROUNDDOWN(BF63/BJ63,3))
D65: J10 | U65: =IF(H65="","",ROUNDDOWN(N65/R65,3)) | AV65: J10 | BM65: =IF(AZ65="","",ROUNDDOWN(BF65/BJ65,3))
N67: =SUM(N47:Q66) -> 12 | U67: =IF(H67="","",ROUNDDOWN(N67/R67,3)) | BF67: =SUM(BF47:BI66) -> 35 | BM67: =IF(AZ67="","",ROUNDDOWN(BF67/BJ67,3))
H69: =IF(N67=0,"","Total") -> Total | N69: =IF(H69="","",SUM(N47:Q66)) -> 12 | R69: =IF(H69="","",SUM(R47:T66)) -> 80 | U69: =IF(H69="","",ROUNDDOWN(N69/R69,3)) -> 0.15 | AZ69: =IF(BF67=0,"","Total") -> Total | BF69: =IF(AZ69="","",SUM(BF47:BI66)) -> 35 | BJ69: =IF(AZ69="","",SUM(BJ47:BL66)) -> 120 | BM69: =IF(AZ69="","",ROUNDDOWN(BF69/BJ69,3)) -> 0.291
A112: Individuel Libre Match | AS112: Individuel Libre 1/4match | CK112: Individuel Handycap
H114: Date | N114: Pts | R114: Rep | U114: Moy. | Y114: Série | AC114: Advers. | AJ114: Equipe | AZ114: Date | BF114: Pts | BJ114: Rep | BM114: Moy. | BQ114: Série | BU114: Advers. | CB114: Equipe | CR114: Date | CX114: Pts | DB114: Rep | DE114: Moy. | DI114: Série | DM114: Advers. | DT114: Equipe
U116: =IF(H116="","",ROUNDDOWN(N116/R116,3)) | BM116: =IF(AZ116="","",ROUNDDOWN(BF116/BJ116,3)) | DE116: =IF(CR116="","",ROUNDDOWN(CX116/DB116,3))
U118: =IF(H118="","",ROUNDDOWN(N118/R118,3)) | BM118: =IF(AZ118="","",ROUNDDOWN(BF118/BJ118,3)) | DE118: =IF(CR118="","",ROUNDDOWN(CX118/DB118,3))
U120: =IF(H120="","",ROUNDDOWN(N120/R120,3)) | BM120: =IF(AZ120="","",ROUNDDOWN(BF120/BJ120,3)) | DE120: =IF(CR120="","",ROUNDDOWN(CX120/DB120,3))
U122: =IF(H122="","",ROUNDDOWN(N122/R122,3)) | BM122: =IF(AZ122="","",ROUNDDOWN(BF122/BJ122,3)) | DE122: =IF(CR122="","",ROUNDDOWN(CX122/DB122,3))
U124: =IF(H124="","",ROUNDDOWN(N124/R124,3)) | BM124: =IF(AZ124="","",ROUNDDOWN(BF124/BJ124,3)) | DE124: =IF(CR124="","",ROUNDDOWN(CX124/DB124,3))
U126: =IF(H126="","",ROUNDDOWN(N126/R126,3)) | BM126: =IF(AZ126="","",ROUNDDOWN(BF126/BJ126,3)) | DE126: =IF(CR126="","",ROUNDDOWN(CX126/DB126,3))
N128: =SUM(N116:Q127) -> 0 | U128: =IF(H128="","",ROUNDDOWN(N128/R128,3)) | BF128: =SUM(BF116:BI127) -> 0 | BM128: =IF(AZ128="","",ROUNDDOWN(BF128/BJ128,3)) | CX128: =SUM(CX116:DA127) -> 0 | DE128: =IF(CR128="","",ROUNDDOWN(CX128/DB128,3))
...

Sheet Di Leo
A1: Di Leo François
H6: Catégorie | Y6: Libre | AO6: Cadre | BF6: 1bande | BW6: 3bandes Match | CM6: 3bandes 1/4match | DD6: 3bandes Match conv.
H8: Pts | L8: Rep | P8: Moy | Y8: =IF(N38="",0,N38)+IF(AD130="",0,AD130)+IF(BF130="",0,BF130)+IF(CX130="",0,CX130) -> 0 | AC8: =IF(R38="",0,R38)+IF(AG130="",0,AG130)+IF(BJ130="",0,BJ130)+IF(DB130="",0,DB130) -> 0 | AG8: =IF(Y8=0,0,ROUNDDOWN(Y8/AC8,3)) -> 0 | AO8: =IF(BF38="",0,BF38)+IF(AC153="",0,AC153)+IF(BF153="",0,BF153) -> 0 | AS8: =IF(BJ38="",0,BJ38)+IF(AG153="",0,AG153)+IF(BJ153="",0,BJ153) -> 0 | AW8: =IF(AO8=0,0,ROUNDDOWN(AO8/AS8,3)) -> 0 | BF8: =IF(CX153="",0,CX153)+IF(AC176="",0,AC176) -> 0 | BJ8: =IF(DB153="",0,DB153)+IF(AG176="",0,AG176) -> 0 | BN8: =IF(BF8=0,0,ROUNDDOWN(BF8/BJ8,3)) -> 0 | BW8: =IF(CX38="",0,CX38)+IF(N69="",0,N69)+IF(N199="",0,N199)+IF(BF199="",0,BF199)+IF(CX199="",0,CX199)+IF(BF176="",0,BF176) -> 0 | CA8: =IF(DB38="",0,DB38)+IF(R69="",0,R69)+IF(R199="",0,R199)+IF(BJ199="",0,BJ199)+IF(DB199="",0,DB199)+IF(BJ176="",0,BJ176) -> 0 | CE8: =IF(BW8=0,0,ROUNDDOWN(BW8/CA8,3)) -> 0 | CM8: =IF(BF69="",0,BF69)+IF(AD199="",0,AD199)+IF(BV199="",0,BV199)+IF(DN199="",0,DN199)+IF(CX176="",0,CX176) -> 7 | CQ8: =IF(BJ69="",0,BJ69)+IF(AG199="",0,AG199)+IF(BY199="",0,BY199)+IF(DQ199="",0,DQ199)+IF(DB176="",0,DB176) -> 40 | CU8: =IF(CM8=0,0,ROUNDDOWN(CM8/CQ8,3)) -> 0.175 | DD8: =SUM(BW8+(CM8*0.7)) -> 4.9 | DH8: =SUM(CA8+CQ8) -> 40 | DL8: =IF(DD8=0,0,ROUNDDOWN(DD8/DH8,3)) -> 0.122
A12: Libre | AS12: Cadre | CK12: 3bandes Billard Match
H14: Date | N14: Pts | R14: Rep | U14: Moy. | Y14: Série | AC14: Advers. | AJ14: Equipe | AZ14: Date | BF14: Pts | BJ14: Rep | BM14: Moy. | BQ14: Série | BU14: Advers. | CB14: Equipe | CR14: Date | CX14: Pts | DB14: Rep | DE14: Moy. | DI14: Série | DM14: Advers. | DT14: Equipe
A16: ITC Classique | D16: J 1 | U16: =IF(H16="","",ROUNDDOWN(N16/R16,3)) | AS16: ITC Classique | AV16: J 1 | BM16: =IF(AZ16="","",ROUNDDOWN(BF16/BJ16,3)) | CK16: ITC Classique | CN16: J 1 | DE16: =IF(CR16="","",ROUNDDOWN(CX16/DB16,3))
D18: J 2 | U18: =IF(H18="","",ROUNDDOWN(N18/R18,3)) | AV18: J 2 | BM18: =IF(AZ18="","",ROUNDDOWN(BF18/BJ18,3)) | CN18: J 2 | DE18: =IF(CR18="","",ROUNDDOWN(CX18/DB18,3))
D20: J 3 | U20: =IF(H20="","",ROUNDDOWN(N20/R20,3)) | AV20: J 3 | BM20: =IF(AZ20="","",ROUNDDOWN(BF20/BJ20,3)) | CN20: J 3 | DE20: =IF(CR20="","",ROUNDDOWN(CX20/DB20,3))
D22: J 4 | U22: =IF(H22="","",ROUNDDOWN(N22/R22,3)) | AV22: J 4 | BM22: =IF(AZ22="","",ROUNDDOWN(BF22/BJ22,3)) | CN22: J 4 | DE22: =IF(CR22="","",ROUNDDOWN(CX22/DB22,3))
D24: J 5 | U24: =IF(H24="","",ROUNDDOWN(N24/R24,3)) | AV24: J 5 | BM24: =IF(AZ24="","",ROUNDDOWN(BF24/BJ24,3)) | CN24: J 5 | DE24: =IF(CR24="","",ROUNDDOWN(CX24/DB24,3))
D26: J 6 | U26: =IF(H26="","",ROUNDDOWN(N26/R26,3)) | AV26: J 6 | BM26: =IF(AZ26="","",ROUNDDOWN(BF26/BJ26,3)) | CN26: J 6 | DE26: =IF(CR26="","",ROUNDDOWN(CX26/DB26,3))
D28: J7 | U28: =IF(H28="","",ROUNDDOWN(N28/R28,3)) | AV28: J7 | BM28: =IF(AZ28="","",ROUNDDOWN(BF28/BJ28,3)) | CN28: J7 | DE28: =IF(CR28="","",ROUNDDOWN(CX28/DB28,3))
D30: J8 | U30: =IF(H30="","",ROUNDDOWN(N30/R30,3)) | AV30: J8 | BM30: =IF(AZ30="","",ROUNDDOWN(BF30/BJ30,3)) | CN30: J8 | DE30: =IF(CR30="","",ROUNDDOWN(CX30/DB30,3))
D32: J9 | U32: =IF(H32="","",ROUNDDOWN(N32/R32,3)) | AV32: J9 | BM32: =IF(AZ32="","",ROUNDDOWN(BF32/BJ32,3)) | CN32: J9 | DE32: =IF(CR32="","",ROUNDDOWN(CX32/DB32,3))
D34: J10 | U34: =IF(H34="","",ROUNDDOWN(N34/R34,3)) | AV34: J10 | BM34: =IF(AZ34="","",ROUNDDOWN(BF34/BJ34,3)) | CN34: J10 | DE34: =IF(CR34="","",ROUNDDOWN(CX34/DB34,3))
